Workbook

Sheet Data_Matrix
A1: Time | B1: ROI1 | C1: ROI2 | D1: ROI3 | E1: ROI4 | F1: ROI5 | G1: ROI6 | H1: ROI7
A2: 0.40699074 | B2: 225.33325 | C2: 232.71642 | D2: 182.48871 | E2: 286.57322 | F2: 277.00135 | H2: 275.53156
A3: 0.41550926 | F3: 305.7491 | G3: 248.77633 | H3: 285.32749
A4: 0.41690972 | B4: 251.86393 | C4: 303.68099 | D4: 179.0768 | F4: 289.53742 | G4: 334.04575 | H4: 280.73595
A5: 0.4169213 | B5: 253.14318 | C5: 290.70686 | D5: 182.93009 | F5: 311.42382 | G5: 341.94384
A6: 0.41693287 | B6: 260.66469 | C6: 291.35152 | D6: 208.95301 | F6: 271.4288 | H6: 254.00268
A7: 0.41694444 | C7: 220.19371 | D7: 179.56721 | F7: 360.42742 | G7: 379.2524
A8: 0.41695602 | D8: 196.62579 | F8: 367.71625 | G8: 387.85152
A9: 0.41696759 | C9: 261.44114 | F9: 359.78061 | G9: 333.16675
A10: 0.41699074 | B10: 193.49812 | C10: 262.10714 | F10: 311.97373
A11: 0.41700231 | C11: 284.73311 | F11: 306.98999
A12: 0.41702546 | B12: 257.20163 | C12: 277.36393 | F12: 304.34935 | G12: 354.36517
A13: 0.41976852 | B13: 333.1879 | C13: 345.63748 | D13: 254.85074 | E13: 331.54912 | F13: 340.81966 | H13: 429.62567
A14: 0.41978009 | B14: 289.87584 | C14: 334.88742 | D14: 200.73531 | E14: 303.05223 | F14: 332.84588 | G14: 430.11621 | H14: 427.62023
A15: 0.41979167 | B15: 299.12922 | C15: 335.9281 | D15: 198.78138 | E15: 294.75708 | F15: 348.44477 | G15: 433.50857 | H15: 422.91165
A16: 0.41980324 | C16: 340.99883 | H16: 405.15188
A17: 0.41981481 | C17: 334.22651 | F17: 309.62907 | G17: 442.31007 | H17: 386.02452
A18: 0.41983796 | C18: 333.11061
A19: 0.41984954 | C19: 342.64678
A20: 0.41986111 | B20: 330.76577 | C20: 331.53421 | D20: 218.72704 | E20: 326.07129
A21: 0.41987269 | B21: 324.15881 | C21: 344.88562 | D21: 216.10759 | E21: 330.36944 | H21: 334.77241
A22: 0.41989583 | B22: 324.43146 | C22: 322.50881 | H22: 363.08533
A23: 0.41990741 | B23: 325.08346 | C23: 322.37367 | D23: 202.9186 | E23: 329.18737 | F23: 307.47509 | H23: 347.39086
A24: 0.41991898 | B24: 318.89795 | C24: 322.17976 | D24: 207.89849 | E24: 330.52079 | F24: 311.57557 | G24: 452.7383 | H24: 368.17393
A25: 0.41993056 | B25: 317.62928 | C25: 313.89274
A26: 0.41994213 | B26: 360.98468 | C26: 348.76075 | D26: 233.85886 | E26: 363.71068
A27: 0.4199537 | B27: 317.50219 | C27: 329.40713 | E27: 333.73396 | H27: 347.00754
A28: 0.41996528 | B28: 334.96613 | C28: 327.2959 | E28: 334.74395
A29: 0.41997685 | B29: 342.43745 | C29: 330.12176 | D29: 191.05478 | E29: 339.43942 | F29: 351.76129 | G29: 430.56261 | H29: 354.45719
A30: 0.41998843 | B30: 340.09466 | C30: 328.91032 | D30: 185.24536 | E30: 337.1319 | F30: 350.23479 | G30: 426.54358 | H30: 344.4645
A31: 0.42 | B31: 337.41801 | C31: 324.56831 | D31: 179.8082 | E31: 337.32474 | F31: 347.46697 | G31: 421.05143 | H31: 330.22653
A32: 0.42001157 | B32: 344.51896 | C32: 325.23702 | D32: 186.23392 | E32: 340.13072 | F32: 356.93366 | G32: 414.0921 | H32: 345.24399
A33: 0.42002315 | B33: 344.19507 | C33: 338.82899 | D33: 216.28451 | E33: 353.91099 | F33: 362.05001 | G33: 433.10695 | H33: 425.335
A34: 0.42003472 | B34: 330.43076 | C34: 326.3566 | D34: 215.85154 | E34: 322.83415 | F34: 329.46405 | G34: 441.73807 | H34: 436.07358
A35: 0.4200463 | B35: 320.62822 | C35: 333.53553 | D35: 209.33095 | E35: 333.3395 | F35: 316.77853 | G35: 457.60189 | H35: 391.34138
A36: 0.42005787 | B36: 339.99598 | C36: 332.33157 | D36: 202.97747 | E36: 344.94476 | F36: 335.51353 | G36: 431.31615 | H36: 376.86761
A37: 0.42006944 | B37: 336.79356 | C37: 328.22235 | D37: 193.98259 | E37: 343.656 | F37: 331.21769 | G37: 428.26384 | H37: 368.66815
A38: 0.42008102 | B38: 338.15096 | C38: 326.82399 | D38: 196.56633 | E38: 342.07672 | F38: 333.88514 | G38: 432.11906 | H38: 368.72815
A39: 0.42009259 | B39: 349.86495 | C39: 336.4404 | D39: 214.85258 | E39: 351.43272 | F39: 350.58842 | G39: 454.06272 | H39: 421.89439
A40: 0.42010417 | B40: 349.63506 | C40: 334.61819 | D40: 208.76446 | E40: 348.21796 | F40: 338.12761 | G40: 440.4345 | H40: 377.57906
...

Sheet Data_Long_Form
A1: ROI Name | B1: Day and Time | C1: Surgery Time (hours:minutes:seconds) | D1: Blood Flow (1/K^2)
A2: ROI7 | B2: 2025-09-04 09:46:04.000 | C2: =+TIME(HOUR(B2),MINUTE(B2),SECOND(B2)) -> 0.40699074 | D2: 225.33325
A3: ROI7 | B3: 2025-09-04 10:00:21.000 | C3: =+TIME(HOUR(B3),MINUTE(B3),SECOND(B3)) -> 0.41690972 | D3: 251.86393
A4: ROI7 | B4: 2025-09-04 10:00:22.000 | C4: =+TIME(HOUR(B4),MINUTE(B4),SECOND(B4)) -> 0.4169213 | D4: 253.14318
A5: ROI7 | B5: 2025-09-04 10:00:23.000 | C5: =+TIME(HOUR(B5),MINUTE(B5),SECOND(B5)) -> 0.41693287 | D5: 260.66469
A6: ROI7 | B6: 2025-09-04 10:00:28.000 | C6: =+TIME(HOUR(B6),MINUTE(B6),SECOND(B6)) -> 0.41699074 | D6: 193.49812
A7: ROI7 | B7: 2025-09-04 10:00:31.000 | C7: =+TIME(HOUR(B7),MINUTE(B7),SECOND(B7)) -> 0.41702546 | D7: 257.20163
A8: ROI7 | B8: 2025-09-04 10:04:28.000 | C8: =+TIME(HOUR(B8),MINUTE(B8),SECOND(B8)) -> 0.41976852 | D8: 333.1879
A9: ROI7 | B9: 2025-09-04 10:04:29.000 | C9: =+TIME(HOUR(B9),MINUTE(B9),SECOND(B9)) -> 0.41978009 | D9: 289.87584
A10: ROI7 | B10: 2025-09-04 10:04:30.000 | C10: =+TIME(HOUR(B10),MINUTE(B10),SECOND(B10)) -> 0.41979167 | D10: 299.12922
A11: ROI7 | B11: 2025-09-04 10:04:36.000 | C11: =+TIME(HOUR(B11),MINUTE(B11),SECOND(B11)) -> 0.41986111 | D11: 330.76577
A12: ROI7 | B12: 2025-09-04 10:04:37.000 | C12: =+TIME(HOUR(B12),MINUTE(B12),SECOND(B12)) -> 0.41987269 | D12: 324.15881
A13: ROI7 | B13: 2025-09-04 10:04:39.000 | C13: =+TIME(HOUR(B13),MINUTE(B13),SECOND(B13)) -> 0.41989583 | D13: 324.43146
... A603: ROI13 | B603: 2025-09-04 10:35:59.000 | C603: =+TIME(HOUR(B603),MINUTE(B603),SECOND(B603)) -> 0.44165509 | D603: 492.6718

Sheet Data_Pivot_Table
A3: Count of ROI Name | B3: Column Labels
A4: Row Labels | B4: ROI10 | C4: ROI11 | D4: ROI12 | E4: ROI13 | F4: ROI7 | G4: ROI8 | H4: ROI9 | I4: Grand Total | K4: Row Labels | L4: ROI7 | M4: ROI8 | N4: ROI9 | O4: ROI10 | P4: ROI11 | Q4: ROI12 | R4: ROI13 | S4: Grand Total | W4: ROI7 | X4: ROI8 | Y4: ROI9 | Z4: ROI10 | AA4: ROI11 | AB4: ROI12 | AC4: ROI13
A5: 0.40699074 | B5: 1 | C5: 1 | E5: 1 | F5: 1 | G5: 1 | H5: 1 | I5: 6 | K5: 0.40699074 | L5: 1 | M5: 1 | N5: 1 | O5: 1 | P5: 1 | R5: 1 | S5: 6 | V5: 0.40699074 | W5: =+IF(SUMIFS(Data_Long_Form!$D:$D,Data_Long_Form!$C:$C,Data_Pivot_Table!$V5,Data_Long_Form!$A:$A,Data_Pivot_Table!W$4)=0,"",SUMIFS(Data_Long_Form!$D:$D,Data_Long_Form!$C:$C,Data_Pivot_Table!$V5,Data_Long_Form!$A:$A,Data_Pivot_Table!W$4)) -> 225.33325 | X5: =+IF(SUMIFS(Data_Long_Form!$D:$D,Data_Long_Form!$C:$C,Data_Pivot_Table!$V5,Data_Long_Form!$A:$A,Data_Pivot_Table!X$4)=0,"",SUMIFS(Data_Long_Form!$D:$D,Data_Long_Form!$C:$C,Data_Pivot_Table!$V5,Data_Long_Form!$A:$A,Data_Pivot_Table!X$4)) -> 232.71642 | Y5: =+IF(SUMIFS(Data_Long_Form!$D:$D,Data_Long_Form!$C:$C,Data_Pivot_Table!$V5,Data_Long_Form!$A:$A,Data_Pivot_Table!Y$4)=0,"",SUMIFS(Data_Long_Form!$D:$D,Data_Long_Form!$C:$C,Data_Pivot_Table!$V5,Data_Long_Form!$A:$A,Data_Pivot_Table!Y$4)) -> 182.48871 | Z5: =+IF(SUMIFS(Data_Long_Form!$D:$D,Data_Long_Form!$C:$C,Data_Pivot_Table!$V5,Data_Long_Form!$A:$A,Data_Pivot_Table!Z$4)=0,"",SUMIFS(Data_Long_Form!$D:$D,Data_Long_Form!$C:$C,Data_Pivot_Table!$V5,Data_Long_Form!$A:$A,Data_Pivot_Table!Z$4)) -> 286.57322 | AA5: =+IF(SUMIFS(Data_Long_Form!$D:$D,Data_Long_Form!$C:$C,Data_Pivot_Table!$V5,Data_Long_Form!$A:$A,Data_Pivot_Table!AA$4)=0,"",SUMIFS(Data_Long_Form!$D:$D,Data_Long_Form!$C:$C,Data_Pivot_Table!$V5,Data_Long_Form!$A:$A,Data_Pivot_Table!AA$4)) -> 277.00135 | AB5: =+IF(SUMIFS(Data_Long_Form!$D:$D,Data_Long_Form!$C:$C,Data_Pivot_Table!$V5,Data_Long_Form!$A:$A,Data_Pivot_Table!AB$4)=0,"",SUMIFS(Data_Long_Form!$D:$D,Data_Long_Form!$C:$C,Data_Pivot_Table!$V5,Data_Long_Form!$A:$A,Data_Pivot_Table!AB$4)) | AC5: =+IF(SUMIFS(Data_Long_Form!$D:$D,Data_Long_Form!$C:$C,Data_Pivot_Table!$V5,Data_Long_Form!$A:$A,Data_Pivot_Table!AC$4)=0,"",SUMIFS(Data_Long_Form!$D:$D,Data_Long_Form!$C:$C,Data_Pivot_Table!$V5,Data_Long_Form!$A:$A,Data_Pivot_Table!AC$4)) -> 275.53156
A6: 0.41550926 | C6: 1 | D6: 1 | E6: 1 | I6: 3 | K6: 0.41550926 | P6: 1 | Q6: 1 | R6: 1 | S6: 3 | V6: 0.41550926 | W6: =+IF(SUMIFS(Data_Long_Form!$D:$D,Data_Long_Form!$C:$C,Data_Pivot_Table!$V6,Data_Long_Form!$A:$A,Data_Pivot_Table!W$4)=0,"",SUMIFS(Data_Long_Form!$D:$D,Data_Long_Form!$C:$C,Data_Pivot_Table!$V6,Data_Long_Form!$A:$A,Data_Pivot_Table!W$4)) | X6: =+IF(SUMIFS(Data_Long_Form!$D:$D,Data_Long_Form!$C:$C,Data_Pivot_Table!$V6,Data_Long_Form!$A:$A,Data_Pivot_Table!X$4)=0,"",SUMIFS(Data_Long_Form!$D:$D,Data_Long_Form!$C:$C,Data_Pivot_Table!$V6,Data_Long_Form!$A:$A,Data_Pivot_Table!X$4)) | Y6: =+IF(SUMIFS(Data_Long_Form!$D:$D,Data_Long_Form!$C:$C,Data_Pivot_Table!$V6,Data_Long_Form!$A:$A,Data_Pivot_Table!Y$4)=0,"",SUMIFS(Data_Long_Form!$D:$D,Data_Long_Form!$C:$C,Data_Pivot_Table!$V6,Data_Long_Form!$A:$A,Data_Pivot_Table!Y$4)) | Z6: =+IF(SUMIFS(Data_Long_Form!$D:$D,Data_Long_Form!$C:$C,Data_Pivot_Table!$V6,Data_Long_Form!$A:$A,Data_Pivot_Table!Z$4)=0,"",SUMIFS(Data_Long_Form!$D:$D,Data_Long_Form!$C:$C,Data_Pivot_Table!$V6,Data_Long_Form!$A:$A,Data_Pivot_Table!Z$4)) | AA6: =+IF(SUMIFS(Data_Long_Form!$D:$D,Data_Long_Form!$C:$C,Data_Pivot_Table!$V6,Data_Long_Form!$A:$A,Data_Pivot_Table!AA$4)=0,"",SUMIFS(Data_Long_Form!$D:$D,Data_Long_Form!$C:$C,Data_Pivot_Table!$V6,Data_Long_Form!$A:$A,Data_Pivot_Table!AA$4)) -> 305.7491 | AB6: =+IF(SUMIFS(Data_Long_Form!$D:$D,Data_Long_Form!$C:$C,Data_Pivot_Table!$V6,Data_Long_Form!$A:$A,Data_Pivot_Table!AB$4)=0,"",SUMIFS(Data_Long_Form!$D:$D,Data_Long_Form!$C:$C,Data_Pivot_Table!$V6,Data_Long_Form!$A:$A,Data_Pivot_Table!AB$4)) -> 248.77633 | AC6: =+IF(SUMIFS(Data_Long_Form!$D:$D,Data_Long_Form!$C:$C,Data_Pivot_Table!$V6,Data_Long_Form!$A:$A,Data_Pivot_Table!AC$4)=0,"",SUMIFS(Data_Long_Form!$D:$D,Data_Long_Form!$C:$C,Data_Pivot_Table!$V6,Data_Long_Form!$A:$A,Data_Pivot_Table!AC$4)) -> 285.32749
A7: 0.41690972 | C7: 1 | D7: 1 | E7: 1 | F7: 1 | G7: 1 | H7: 1 | I7: 6 | K7: 0.41690972 | L7: 1 | M7: 1 | N7: 1 | P7: 1 | Q7: 1 | R7: 1 | S7: 6 | V7: 0.41690972 | W7: =+IF(SUMIFS(Data_Long_Form!$D:$D,Data_Long_Form!$C:$C,Data_Pivot_Table!$V7,Data_Long_Form!$A:$A,Data_Pivot_Table!W$4)=0,"",SUMIFS(Data_Long_Form!$D:$D,Data_Long_Form!$C:$C,Data_Pivot_Table!$V7,Data_Long_Form!$A:$A,Data_Pivot_Table!W$4)) -> 251.86393 | X7: =+IF(SUMIFS(Data_Long_Form!$D:$D,Data_Long_Form!$C:$C,Data_Pivot_Table!$V7,Data_Long_Form!$A:$A,Data_Pivot_Table!X$4)=0,"",SUMIFS(Data_Long_Form!$D:$D,Data_Long_Form!$C:$C,Data_Pivot_Table!$V7,Data_Long_Form!$A:$A,Data_Pivot_Table!X$4)) -> 303.68099 | Y7: =+IF(SUMIFS(Data_Long_Form!$D:$D,Data_Long_Form!$C:$C,Data_Pivot_Table!$V7,Data_Long_Form!$A:$A,Data_Pivot_Table!Y$4)=0,"",SUMIFS(Data_Long_Form!$D:$D,Data_Long_Form!$C:$C,Data_Pivot_Table!$V7,Data_Long_Form!$A:$A,Data_Pivot_Table!Y$4)) -> 179.0768 | Z7: =+IF(SUMIFS(Data_Long_Form!$D:$D,Data_Long_Form!$C:$C,Data_Pivot_Table!$V7,Data_Long_Form!$A:$A,Data_Pivot_Table!Z$4)=0,"",SUMIFS(Data_Long_Form!$D:$D,Data_Long_Form!$C:$C,Data_Pivot_Table!$V7,Data_Long_Form!$A:$A,Data_Pivot_Table!Z$4)) | AA7: =+IF(SUMIFS(Data_Long_Form!$D:$D,Data_Long_Form!$C:$C,Data_Pivot_Table!$V7,Data_Long_Form!$A:$A,Data_Pivot_Table!AA$4)=0,"",SUMIFS(Data_Long_Form!$D:$D,Data_Long_Form!$C:$C,Data_Pivot_Table!$V7,Data_Long_Form!$A:$A,Data_Pivot_Table!AA$4)) -> 289.53742 | AB7: =+IF(SUMIFS(Data_Long_Form!$D:$D,Data_Long_Form!$C:$C,Data_Pivot_Table!$V7,Data_Long_Form!$A:$A,Data_Pivot_Table!AB$4)=0,"",SUMIFS(Data_Long_Form!$D:$D,Data_Long_Form!$C:$C,Data_Pivot_Table!$V7,Data_Long_Form!$A:$A,Data_Pivot_Table!AB$4)) -> 334.04575 | AC7: =+IF(SUMIFS(Data_Long_Form!$D:$D,Data_Long_Form!$C:$C,Data_Pivot_Table!$V7,Data_Long_Form!$A:$A,Data_Pivot_Table!AC$4)=0,"",SUMIFS(Data_Long_Form!$D:$D,Data_Long_Form!$C:$C,Data_Pivot_Table!$V7,Data_Long_Form!$A:$A,Data_Pivot_Table!AC$4)) -> 280.73595
A8: 0.4169213 | C8: 1 | D8: 1 | F8: 1 | G8: 1 | H8: 1 | I8: 5 | K8: 0.4169213 | L8: 1 | M8: 1 | N8: 1 | P8: 1 | Q8: 1 | S8: 5 | V8: 0.4169213 | W8: =+IF(SUMIFS(Data_Long_Form!$D:$D,Data_Long_Form!$C:$C,Data_Pivot_Table!$V8,Data_Long_Form!$A:$A,Data_Pivot_Table!W$4)=0,"",SUMIFS(Data_Long_Form!$D:$D,Data_Long_Form!$C:$C,Data_Pivot_Table!$V8,Data_Long_Form!$A:$A,Data_Pivot_Table!W$4)) -> 253.14318 | X8: =+IF(SUMIFS(Data_Long_Form!$D:$D,Data_Long_Form!$C:$C,Data_Pivot_Table!$V8,Data_Long_Form!$A:$A,Data_Pivot_Table!X$4)=0,"",SUMIFS(Data_Long_Form!$D:$D,Data_Long_Form!$C:$C,Data_Pivot_Table!$V8,Data_Long_Form!$A:$A,Data_Pivot_Table!X$4)) -> 290.70686 | Y8: =+IF(SUMIFS(Data_Long_Form!$D:$D,Data_Long_Form!$C:$C,Data_Pivot_Table!$V8,Data_Long_Form!$A:$A,Data_Pivot_Table!Y$4)=0,"",SUMIFS(Data_Long_Form!$D:$D,Data_Long_Form!$C:$C,Data_Pivot_Table!$V8,Data_Long_Form!$A:$A,Data_Pivot_Table!Y$4)) -> 182.93009 | Z8: =+IF(SUMIFS(Data_Long_Form!$D:$D,Data_Long_Form!$C:$C,Data_Pivot_Table!$V8,Data_Long_Form!$A:$A,Data_Pivot_Table!Z$4)=0,"",SUMIFS(Data_Long_Form!$D:$D,Data_Long_Form!$C:$C,Data_Pivot_Table!$V8,Data_Long_Form!$A:$A,Data_Pivot_Table!Z$4)) | AA8: =+IF(SUMIFS(Data_Long_Form!$D:$D,Data_Long_Form!$C:$C,Data_Pivot_Table!$V8,Data_Long_Form!$A:$A,Data_Pivot_Table!AA$4)=0,"",SUMIFS(Data_Long_Form!$D:$D,Data_Long_Form!$C:$C,Data_Pivot_Table!$V8,Data_Long_Form!$A:$A,Data_Pivot_Table!AA$4)) -> 311.42382 | AB8: =+IF(SUMIFS(Data_Long_Form!$D:$D,Data_Long_Form!$C:$C,Data_Pivot_Table!$V8,Data_Long_Form!$A:$A,Data_Pivot_Table!AB$4)=0,"",SUMIFS(Data_Long_Form!$D:$D,Data_Long_Form!$C:$C,Data_Pivot_Table!$V8,Data_Long_Form!$A:$A,Data_Pivot_Table!AB$4)) -> 341.94384 | AC8: =+IF(SUMIFS(Data_Long_Form!$D:$D,Data_Long_Form!$C:$C,Data_Pivot_Table!$V8,Data_Long_Form!$A:$A,Data_Pivot_Table!AC$4)=0,"",SUMIFS(Data_Long_Form!$D:$D,Data_Long_Form!$C:$C,Data_Pivot_Table!$V8,Data_Long_Form!$A:$A,Data_Pivot_Table!AC$4))
A9: 0.41693287 | C9: 1 | E9: 1 | F9: 1 | G9: 1 | H9: 1 | I9: 5 | K9: 0.41693287 | L9: 1 | M9: 1 | N9: 1 | P9: 1 | R9: 1 | S9: 5 | V9: 0.41693287 | W9: =+IF(SUMIFS(Data_Long_Form!$D:$D,Data_Long_Form!$C:$C,Data_Pivot_Table!$V9,Data_Long_Form!$A:$A,Data_Pivot_Table!W$4)=0,"",SUMIFS(Data_Long_Form!$D:$D,Data_Long_Form!$C:$C,Data_Pivot_Table!$V9,Data_Long_Form!$A:$A,Data_Pivot_Table!W$4)) -> 260.66469 | X9: =+IF(SUMIFS(Data_Long_Form!$D:$D,Data_Long_Form!$C:$C,Data_Pivot_Table!$V9,Data_Long_Form!$A:$A,Data_Pivot_Table!X$4)=0,"",SUMIFS(Data_Long_Form!$D:$D,Data_Long_Form!$C:$C,Data_Pivot_Table!$V9,Data_Long_Form!$A:$A,Data_Pivot_Table!X$4)) -> 291.35152 | Y9: =+IF(SUMIFS(Data_Long_Form!$D:$D,Data_Long_Form!$C:$C,Data_Pivot_Table!$V9,Data_Long_Form!$A:$A,Data_Pivot_Table!Y$4)=0,"",SUMIFS(Data_Long_Form!$D:$D,Data_Long_Form!$C:$C,Data_Pivot_Table!$V9,Data_Long_Form!$A:$A,Data_Pivot_Table!Y$4)) -> 208.95301 | Z9: =+IF(SUMIFS(Data_Long_Form!$D:$D,Data_Long_Form!$C:$C,Data_Pivot_Table!$V9,Data_Long_Form!$A:$A,Data_Pivot_Table!Z$4)=0,"",SUMIFS(Data_Long_Form!$D:$D,Data_Long_Form!$C:$C,Data_Pivot_Table!$V9,Data_Long_Form!$A:$A,Data_Pivot_Table!Z$4)) | AA9: =+IF(SUMIFS(Data_Long_Form!$D:$D,Data_Long_Form!$C:$C,Data_Pivot_Table!$V9,Data_Long_Form!$A:$A,Data_Pivot_Table!AA$4)=0,"",SUMIFS(Data_Long_Form!$D:$D,Data_Long_Form!$C:$C,Data_Pivot_Table!$V9,Data_Long_Form!$A:$A,Data_Pivot_Table!AA$4)) -> 271.4288 | AB9: =+IF(SUMIFS(Data_Long_Form!$D:$D,Data_Long_Form!$C:$C,Data_Pivot_Table!$V9,Data_Long_Form!$A:$A,Data_Pivot_Table!AB$4)=0,"",SUMIFS(Data_Long_Form!$D:$D,Data_Long_Form!$C:$C,Data_Pivot_Table!$V9,Data_Long_Form!$A:$A,Data_Pivot_Table!AB$4)) | AC9: =+IF(SUMIFS(Data_Long_Form!$D:$D,Data_Long_Form!$C:$C,Data_Pivot_Table!$V9,Data_Long_Form!$A:$A,Data_Pivot_Table!AC$4)=0,"",SUMIFS(Data_Long_Form!$D:$D,Data_Long_Form!$C:$C,Data_Pivot_Table!$V9,Data_Long_Form!$A:$A,Data_Pivot_Table!AC$4)) -> 254.00268
A10: 0.41694444 | C10: 1 | D10: 1 | G10: 1 | H10: 1 | I10: 4 | K10: 0.41694444 | M10: 1 | N10: 1 | P10: 1 | Q10: 1 | S10: 4 | V10: 0.41694444 | W10: =+IF(SUMIFS(Data_Long_Form!$D:$D,Data_Long_Form!$C:$C,Data_Pivot_Table!$V10,Data_Long_Form!$A:$A,Data_Pivot_Table!W$4)=0,"",SUMIFS(Data_Long_Form!$D:$D,Data_Long_Form!$C:$C,Data_Pivot_Table!$V10,Data_Long_Form!$A:$A,Data_Pivot_Table!W$4)) | X10: =+IF(SUMIFS(Data_Long_Form!$D:$D,Data_Long_Form!$C:$C,Data_Pivot_Table!$V10,Data_Long_Form!$A:$A,Data_Pivot_Table!X$4)=0,"",SUMIFS(Data_Long_Form!$D:$D,Data_Long_Form!$C:$C,Data_Pivot_Table!$V10,Data_Long_Form!$A:$A,Data_Pivot_Table!X$4)) -> 220.19371 | Y10: =+IF(SUMIFS(Data_Long_Form!$D:$D,Data_Long_Form!$C:$C,Data_Pivot_Table!$V10,Data_Long_Form!$A:$A,Data_Pivot_Table!Y$4)=0,"",SUMIFS(Data_Long_Form!$D:$D,Data_Long_Form!$C:$C,Data_Pivot_Table!$V10,Data_Long_Form!$A:$A,Data_Pivot_Table!Y$4)) -> 179.56721 | Z10: =+IF(SUMIFS(Data_Long_Form!$D:$D,Data_Long_Form!$C:$C,Data_Pivot_Table!$V10,Data_Long_Form!$A:$A,Data_Pivot_Table!Z$4)=0,"",SUMIFS(Data_Long_Form!$D:$D,Data_Long_Form!$C:$C,Data_Pivot_Table!$V10,Data_Long_Form!$A:$A,Data_Pivot_Table!Z$4)) | AA10: =+IF(SUMIFS(Data_Long_Form!$D:$D,Data_Long_Form!$C:$C,Data_Pivot_Table!$V10,Data_Long_Form!$A:$A,Data_Pivot_Table!AA$4)=0,"",SUMIFS(Data_Long_Form!$D:$D,Data_Long_Form!$C:$C,Data_Pivot_Table!$V10,Data_Long_Form!$A:$A,Data_Pivot_Table!AA$4)) -> 360.42742 | AB10: =+IF(SUMIFS(Data_Long_Form!$D:$D,Data_Long_Form!$C:$C,Data_Pivot_Table!$V10,Data_Long_Form!$A:$A,Data_Pivot_Table!AB$4)=0,"",SUMIFS(Data_Long_Form!$D:$D,Data_Long_Form!$C:$C,Data_Pivot_Table!$V10,Data_Long_Form!$A:$A,Data_Pivot_Table!AB$4)) -> 379.2524 | AC10: =+IF(SUMIFS(Data_Long_Form!$D:$D,Data_Long_Form!$C:$C,Data_Pivot_Table!$V10,Data_Long_Form!$A:$A,Data_Pivot_Table!AC$4)=0,"",SUMIFS(Data_Long_Form!$D:$D,Data_Long_Form!$C:$C,Data_Pivot_Table!$V10,Data_Long_Form!$A:$A,Data_Pivot_Table!AC$4))
A11: 0.41695602 | C11: 1 | D11: 1 | H11: 1 | I11: 3 | K11: 0.41695602 | N11: 1 | P11: 1 | Q11: 1 | S11: 3 | V11: 0.41695602 | W11: =+IF(SUMIFS(Data_Long_Form!$D:$D,Data_Long_Form!$C:$C,Data_Pivot_Table!$V11,Data_Long_Form!$A:$A,Data_Pivot_Table!W$4)=0,"",SUMIFS(Data_Long_Form!$D:$D,Data_Long_Form!$C:$C,Data_Pivot_Table!$V11,Data_Long_Form!$A:$A,Data_Pivot_Table!W$4)) | X11: =+IF(SUMIFS(Data_Long_Form!$D:$D,Data_Long_Form!$C:$C,Data_Pivot_Table!$V11,Data_Long_Form!$A:$A,Data_Pivot_Table!X$4)=0,"",SUMIFS(Data_Long_Form!$D:$D,Data_Long_Form!$C:$C,Data_Pivot_Table!$V11,Data_Long_Form!$A:$A,Data_Pivot_Table!X$4)) | Y11: =+IF(SUMIFS(Data_Long_Form!$D:$D,Data_Long_Form!$C:$C,Data_Pivot_Table!$V11,Data_Long_Form!$A:$A,Data_Pivot_Table!Y$4)=0,"",SUMIFS(Data_Long_Form!$D:$D,Data_Long_Form!$C:$C,Data_Pivot_Table!$V11,Data_Long_Form!$A:$A,Data_Pivot_Table!Y$4)) -> 196.62579 | Z11: =+IF(SUMIFS(Data_Long_Form!$D:$D,Data_Long_Form!$C:$C,Data_Pivot_Table!$V11,Data_Long_Form!$A:$A,Data_Pivot_Table!Z$4)=0,"",SUMIFS(Data_Long_Form!$D:$D,Data_Long_Form!$C:$C,Data_Pivot_Table!$V11,Data_Long_Form!$A:$A,Data_Pivot_Table!Z$4)) | AA11: =+IF(SUMIFS(Data_Long_Form!$D:$D,Data_Long_Form!$C:$C,Data_Pivot_Table!$V11,Data_Long_Form!$A:$A,Data_Pivot_Table!AA$4)=0,"",SUMIFS(Data_Long_Form!$D:$D,Data_Long_Form!$C:$C,Data_Pivot_Table!$V11,Data_Long_Form!$A:$A,Data_Pivot_Table!AA$4)) -> 367.71625 | AB11: =+IF(SUMIFS(Data_Long_Form!$D:$D,Data_Long_Form!$C:$C,Data_Pivot_Table!$V11,Data_Long_Form!$A:$A,Data_Pivot_Table!AB$4)=0,"",SUMIFS(Data_Long_Form!$D:$D,Data_Long_Form!$C:$C,Data_Pivot_Table!$V11,Data_Long_Form!$A:$A,Data_Pivot_Table!AB$4)) -> 387.85152 | AC11: =+IF(SUMIFS(Data_Long_Form!$D:$D,Data_Long_Form!$C:$C,Data_Pivot_Table!$V11,Data_Long_Form!$A:$A,Data_Pivot_Table!AC$4)=0,"",SUMIFS(Data_Long_Form!$D:$D,Data_Long_Form!$C:$C,Data_Pivot_Table!$V11,Data_Long_Form!$A:$A,Data_Pivot_Table!AC$4))
A12: 0.41696759 | C12: 1 | D12: 1 | G12: 1 | I12: 3 | K12: 0.41696759 | M12: 1 | P12: 1 | Q12: 1 | S12: 3 | V12: 0.41696759 | W12: =+IF(SUMIFS(Data_Long_Form!$D:$D,Data_Long_Form!$C:$C,Data_Pivot_Table!$V12,Data_Long_Form!$A:$A,Data_Pivot_Table!W$4)=0,"",SUMIFS(Data_Long_Form!$D:$D,Data_Long_Form!$C:$C,Data_Pivot_Table!$V12,Data_Long_Form!$A:$A,Data_Pivot_Table!W$4)) | X12: =+IF(SUMIFS(Data_Long_Form!$D:$D,Data_Long_Form!$C:$C,Data_Pivot_Table!$V12,Data_Long_Form!$A:$A,Data_Pivot_Table!X$4)=0,"",SUMIFS(Data_Long_Form!$D:$D,Data_Long_Form!$C:$C,Data_Pivot_Table!$V12,Data_Long_Form!$A:$A,Data_Pivot_Table!X$4)) -> 261.44114 | Y12: =+IF(SUMIFS(Data_Long_Form!$D:$D,Data_Long_Form!$C:$C,Data_Pivot_Table!$V12,Data_Long_Form!$A:$A,Data_Pivot_Table!Y$4)=0,"",SUMIFS(Data_Long_Form!$D:$D,Data_Long_Form!$C:$C,Data_Pivot_Table!$V12,Data_Long_Form!$A:$A,Data_Pivot_Table!Y$4)) | Z12: =+IF(SUMIFS(Data_Long_Form!$D:$D,Data_Long_Form!$C:$C,Data_Pivot_Table!$V12,Data_Long_Form!$A:$A,Data_Pivot_Table!Z$4)=0,"",SUMIFS(Data_Long_Form!$D:$D,Data_Long_Form!$C:$C,Data_Pivot_Table!$V12,Data_Long_Form!$A:$A,Data_Pivot_Table!Z$4)) | AA12: =+IF(SUMIFS(Data_Long_Form!$D:$D,Data_Long_Form!$C:$C,Data_Pivot_Table!$V12,Data_Long_Form!$A:$A,Data_Pivot_Table!AA$4)=0,"",SUMIFS(Data_Long_Form!$D:$D,Data_Long_Form!$C:$C,Data_Pivot_Table!$V12,Data_Long_Form!$A:$A,Data_Pivot_Table!AA$4)) -> 359.78061 | AB12: =+IF(SUMIFS(Data_Long_Form!$D:$D,Data_Long_Form!$C:$C,Data_Pivot_Table!$V12,Data_Long_Form!$A:$A,Data_Pivot_Table!AB$4)=0,"",SUMIFS(Data_Long_Form!$D:$D,Data_Long_Form!$C:$C,Data_Pivot_Table!$V12,Data_Long_Form!$A:$A,Data_Pivot_Table!AB$4)) -> 333.16675 | AC12: =+IF(SUMIFS(Data_Long_Form!$D:$D,Data_Long_Form!$C:$C,Data_Pivot_Table!$V12,Data_Long_Form!$A:$A,Data_Pivot_Table!AC$4)=0,"",SUMIFS(Data_Long_Form!$D:$D,Data_Long_Form!$C:$C,Data_Pivot_Table!$V12,Data_Long_Form!$A:$A,Data_Pivot_Table!AC$4))
A13: 0.41699074 | C13: 1 | F13: 1 | G13: 1 | I13: 3 | K13: 0.41699074 | L13: 1 | M13: 1 | P13: 1 | S13: 3 | V13: 0.41699074 | W13: =+IF(SUMIFS(Data_Long_Form!$D:$D,Data_Long_Form!$C:$C,Data_Pivot_Table!$V13,Data_Long_Form!$A:$A,Data_Pivot_Table!W$4)=0,"",SUMIFS(Data_Long_Form!$D:$D,Data_Long_Form!$C:$C,Data_Pivot_Table!$V13,Data_Long_Form!$A:$A,Data_Pivot_Table!W$4)) -> 193.49812 | X13: =+IF(SUMIFS(Data_Long_Form!$D:$D,Data_Long_Form!$C:$C,Data_Pivot_Table!$V13,Data_Long_Form!$A:$A,Data_Pivot_Table!X$4)=0,"",SUMIFS(Data_Long_Form!$D:$D,Data_Long_Form!$C:$C,Data_Pivot_Table!$V13,Data_Long_Form!$A:$A,Data_Pivot_Table!X$4)) -> 262.10714 | Y13: =+IF(SUMIFS(Data_Long_Form!$D:$D,Data_Long_Form!$C:$C,Data_Pivot_Table!$V13,Data_Long_Form!$A:$A,Data_Pivot_Table!Y$4)=0,"",SUMIFS(Data_Long_Form!$D:$D,Data_Long_Form!$C:$C,Data_Pivot_Table!$V13,Data_Long_Form!$A:$A,Data_Pivot_Table!Y$4)) | Z13: =+IF(SUMIFS(Data_Long_Form!$D:$D,Data_Long_Form!$C:$C,Data_Pivot_Table!$V13,Data_Long_Form!$A:$A,Data_Pivot_Table!Z$4)=0,"",SUMIFS(Data_Long_Form!$D:$D,Data_Long_Form!$C:$C,Data_Pivot_Table!$V13,Data_Long_Form!$A:$A,Data_Pivot_Table!Z$4)) | AA13: =+IF(SUMIFS(Data_Long_Form!$D:$D,Data_Long_Form!$C:$C,Data_Pivot_Table!$V13,Data_Long_Form!$A:$A,Data_Pivot_Table!AA$4)=0,"",SUMIFS(Data_Long_Form!$D:$D,Data_Long_Form!$C:$C,Data_Pivot_Table!$V13,Data_Long_Form!$A:$A,Data_Pivot_Table!AA$4)) -> 311.97373 | AB13: =+IF(SUMIFS(Data_Long_Form!$D:$D,Data_Long_Form!$C:$C,Data_Pivot_Table!$V13,Data_Long_Form!$A:$A,Data_Pivot_Table!AB$4)=0,"",SUMIFS(Data_Long_Form!$D:$D,Data_Long_Form!$C:$C,Data_Pivot_Table!$V13,Data_Long_Form!$A:$A,Data_Pivot_Table!AB$4)) | AC13: =+IF(SUMIFS(Data_Long_Form!$D:$D,Data_Long_Form!$C:$C,Data_Pivot_Table!$V13,Data_Long_Form!$A:$A,Data_Pivot_Table!AC$4)=0,"",SUMIFS(Data_Long_Form!$D:$D,Data_Long_Form!$C:$C,Data_Pivot_Table!$V13,Data_Long_Form!$A:$A,Data_Pivot_Table!AC$4))
A14: 0.41700231 | C14: 1 | G14: 1 | I14: 2 | K14: 0.41700231 | M14: 1 | P14: 1 | S14: 2 | V14: 0.41700231 | W14: =+IF(SUMIFS(Data_Long_Form!$D:$D,Data_Long_Form!$C:$C,Data_Pivot_Table!$V14,Data_Long_Form!$A:$A,Data_Pivot_Table!W$4)=0,"",SUMIFS(Data_Long_Form!$D:$D,Data_Long_Form!$C:$C,Data_Pivot_Table!$V14,Data_Long_Form!$A:$A,Data_Pivot_Table!W$4)) | X14: =+IF(SUMIFS(Data_Long_Form!$D:$D,Data_Long_Form!$C:$C,Data_Pivot_Table!$V14,Data_Long_Form!$A:$A,Data_Pivot_Table!X$4)=0,"",SUMIFS(Data_Long_Form!$D:$D,Data_Long_Form!$C:$C,Data_Pivot_Table!$V14,Data_Long_Form!$A:$A,Data_Pivot_Table!X$4)) -> 284.73311 | Y14: =+IF(SUMIFS(Data_Long_Form!$D:$D,Data_Long_Form!$C:$C,Data_Pivot_Table!$V14,Data_Long_Form!$A:$A,Data_Pivot_Table!Y$4)=0,"",SUMIFS(Data_Long_Form!$D:$D,Data_Long_Form!$C:$C,Data_Pivot_Table!$V14,Data_Long_Form!$A:$A,Data_Pivot_Table!Y$4)) | Z14: =+IF(SUMIFS(Data_Long_Form!$D:$D,Data_Long_Form!$C:$C,Data_Pivot_Table!$V14,Data_Long_Form!$A:$A,Data_Pivot_Table!Z$4)=0,"",SUMIFS(Data_Long_Form!$D:$D,Data_Long_Form!$C:$C,Data_Pivot_Table!$V14,Data_Long_Form!$A:$A,Data_Pivot_Table!Z$4)) | AA14: =+IF(SUMIFS(Data_Long_Form!$D:$D,Data_Long_Form!$C:$C,Data_Pivot_Table!$V14,Data_Long_Form!$A:$A,Data_Pivot_Table!AA$4)=0,"",SUMIFS(Data_Long_Form!$D:$D,Data_Long_Form!$C:$C,Data_Pivot_Table!$V14,Data_Long_Form!$A:$A,Data_Pivot_Table!AA$4)) -> 306.98999 | AB14: =+IF(SUMIFS(Data_Long_Form!$D:$D,Data_Long_Form!$C:$C,Data_Pivot_Table!$V14,Data_Long_Form!$A:$A,Data_Pivot_Table!AB$4)=0,"",SUMIFS(Data_Long_Form!$D:$D,Data_Long_Form!$C:$C,Data_Pivot_Table!$V14,Data_Long_Form!$A:$A,Data_Pivot_Table!AB$4)) | AC14: =+IF(SUMIFS(Data_Long_Form!$D:$D,Data_Long_Form!$C:$C,Data_Pivot_Table!$V14,Data_Long_Form!$A:$A,Data_Pivot_Table!AC$4)=0,"",SUMIFS(Data_Long_Form!$D:$D,Data_Long_Form!$C:$C,Data_Pivot_Table!$V14,Data_Long_Form!$A:$A,Data_Pivot_Table!AC$4))
A15: 0.41702546 | C15: 1 | D15: 1 | F15: 1 | G15: 1 | I15: 4 | K15: 0.41702546 | L15: 1 | M15: 1 | P15: 1 | Q15: 1 | S15: 4 | V15: 0.41702546 | W15: =+IF(SUMIFS(Data_Long_Form!$D:$D,Data_Long_Form!$C:$C,Data_Pivot_Table!$V15,Data_Long_Form!$A:$A,Data_Pivot_Table!W$4)=0,"",SUMIFS(Data_Long_Form!$D:$D,Data_Long_Form!$C:$C,Data_Pivot_Table!$V15,Data_Long_Form!$A:$A,Data_Pivot_Table!W$4)) -> 257.20163 | X15: =+IF(SUMIFS(Data_Long_Form!$D:$D,Data_Long_Form!$C:$C,Data_Pivot_Table!$V15,Data_Long_Form!$A:$A,Data_Pivot_Table!X$4)=0,"",SUMIFS(Data_Long_Form!$D:$D,Data_Long_Form!$C:$C,Data_Pivot_Table!$V15,Data_Long_Form!$A:$A,Data_Pivot_Table!X$4)) -> 277.36393 | Y15: =+IF(SUMIFS(Data_Long_Form!$D:$D,Data_Long_Form!$C:$C,Data_Pivot_Table!$V15,Data_Long_Form!$A:$A,Data_Pivot_Table!Y$4)=0,"",SUMIFS(Data_Long_Form!$D:$D,Data_Long_Form!$C:$C,Data_Pivot_Table!$V15,Data_Long_Form!$A:$A,Data_Pivot_Table!Y$4)) | Z15: =+IF(SUMIFS(Data_Long_Form!$D:$D,Data_Long_Form!$C:$C,Data_Pivot_Table!$V15,Data_Long_Form!$A:$A,Data_Pivot_Table!Z$4)=0,"",SUMIFS(Data_Long_Form!$D:$D,Data_Long_Form!$C:$C,Data_Pivot_Table!$V15,Data_Long_Form!$A:$A,Data_Pivot_Table!Z$4)) | AA15: =+IF(SUMIFS(Data_Long_Form!$D:$D,Data_Long_Form!$C:$C,Data_Pivot_Table!$V15,Data_Long_Form!$A:$A,Data_Pivot_Table!AA$4)=0,"",SUMIFS(Data_Long_Form!$D:$D,Data_Long_Form!$C:$C,Data_Pivot_Table!$V15,Data_Long_Form!$A:$A,Data_Pivot_Table!AA$4)) -> 304.34935 | AB15: =+IF(SUMIFS(Data_Long_Form!$D:$D,Data_Long_Form!$C:$C,Data_Pivot_Table!$V15,Data_Long_Form!$A:$A,Data_Pivot_Table!AB$4)=0,"",SUMIFS(Data_Long_Form!$D:$D,Data_Long_Form!$C:$C,Data_Pivot_Table!$V15,Data_Long_Form!$A:$A,Data_Pivot_Table!AB$4)) -> 354.36517 | AC15: =+IF(SUMIFS(Data_Long_Form!$D:$D,Data_Long_Form!$C:$C,Data_Pivot_Table!$V15,Data_Long_Form!$A:$A,Data_Pivot_Table!AC$4)=0,"",SUMIFS(Data_Long_Form!$D:$D,Data_Long_Form!$C:$C,Data_Pivot_Table!$V15,Data_Long_Form!$A:$A,Data_Pivot_Table!AC$4))
A16: 0.41976852 | B16: 1 | C16: 1 | E16: 1 | F16: 1 | G16: 1 | H16: 1 | I16: 6 | K16: 0.41976852 | L16: 1 | M16: 1 | N16: 1 | O16: 1 | P16: 1 | R16: 1 | S16: 6 | V16: 0.41976852 | W16: =+IF(SUMIFS(Data_Long_Form!$D:$D,Data_Long_Form!$C:$C,Data_Pivot_Table!$V16,Data_Long_Form!$A:$A,Data_Pivot_Table!W$4)=0,"",SUMIFS(Data_Long_Form!$D:$D,Data_Long_Form!$C:$C,Data_Pivot_Table!$V16,Data_Long_Form!$A:$A,Data_Pivot_Table!W$4)) -> 333.1879 | X16: =+IF(SUMIFS(Data_Long_Form!$D:$D,Data_Long_Form!$C:$C,Data_Pivot_Table!$V16,Data_Long_Form!$A:$A,Data_Pivot_Table!X$4)=0,"",SUMIFS(Data_Long_Form!$D:$D,Data_Long_Form!$C:$C,Data_Pivot_Table!$V16,Data_Long_Form!$A:$A,Data_Pivot_Table!X$4)) -> 345.63748 | Y16: =+IF(SUMIFS(Data_Long_Form!$D:$D,Data_Long_Form!$C:$C,Data_Pivot_Table!$V16,Data_Long_Form!$A:$A,Data_Pivot_Table!Y$4)=0,"",SUMIFS(Data_Long_Form!$D:$D,Data_Long_Form!$C:$C,Data_Pivot_Table!$V16,Data_Long_Form!$A:$A,Data_Pivot_Table!Y$4)) -> 254.85074 | Z16: =+IF(SUMIFS(Data_Long_Form!$D:$D,Data_Long_Form!$C:$C,Data_Pivot_Table!$V16,Data_Long_Form!$A:$A,Data_Pivot_Table!Z$4)=0,"",SUMIFS(Data_Long_Form!$D:$D,Data_Long_Form!$C:$C,Data_Pivot_Table!$V16,Data_Long_Form!$A:$A,Data_Pivot_Table!Z$4)) -> 331.54912 | AA16: =+IF(SUMIFS(Data_Long_Form!$D:$D,Data_Long_Form!$C:$C,Data_Pivot_Table!$V16,Data_Long_Form!$A:$A,Data_Pivot_Table!AA$4)=0,"",SUMIFS(Data_Long_Form!$D:$D,Data_Long_Form!$C:$C,Data_Pivot_Table!$V16,Data_Long_Form!$A:$A,Data_Pivot_Table!AA$4)) -> 340.81966 | AB16: =+IF(SUMIFS(Data_Long_Form!$D:$D,Data_Long_Form!$C:$C,Data_Pivot_Table!$V16,Data_Long_Form!$A:$A,Data_Pivot_Table!AB$4)=0,"",SUMIFS(Data_Long_Form!$D:$D,Data_Long_Form!$C:$C,Data_Pivot_Table!$V16,Data_Long_Form!$A:$A,Data_Pivot_Table!AB$4)) | AC16: =+IF(SUMIFS(Data_Long_Form!$D:$D,Data_Long_Form!$C:$C,Data_Pivot_Table!$V16,Data_Long_Form!$A:$A,Data_Pivot_Table!AC$4)=0,"",SUMIFS(Data_Long_Form!$D:$D,Data_Long_Form!$C:$C,Data_Pivot_Table!$V16,Data_Long_Form!$A:$A,Data_Pivot_Table!AC$4)) -> 429.62567
A17: 0.41978009 | B17: 1 | C17: 1 | D17: 1 | E17: 1 | F17: 1 | G17: 1 | H17: 1 | I17: 7 | K17: 0.41978009 | L17: 1 | M17: 1 | N17: 1 | O17: 1 | P17: 1 | Q17: 1 | R17: 1 | S17: 7 | V17: 0.41978009 | W17: =+IF(SUMIFS(Data_Long_Form!$D:$D,Data_Long_Form!$C:$C,Data_Pivot_Table!$V17,Data_Long_Form!$A:$A,Data_Pivot_Table!W$4)=0,"",SUMIFS(Data_Long_Form!$D:$D,Data_Long_Form!$C:$C,Data_Pivot_Table!$V17,Data_Long_Form!$A:$A,Data_Pivot_Table!W$4)) -> 289.87584 | X17: =+IF(SUMIFS(Data_Long_Form!$D:$D,Data_Long_Form!$C:$C,Data_Pivot_Table!$V17,Data_Long_Form!$A:$A,Data_Pivot_Table!X$4)=0,"",SUMIFS(Data_Long_Form!$D:$D,Data_Long_Form!$C:$C,Data_Pivot_Table!$V17,Data_Long_Form!$A:$A,Data_Pivot_Table!X$4)) -> 334.88742 | Y17: =+IF(SUMIFS(Data_Long_Form!$D:$D,Data_Long_Form!$C:$C,Data_Pivot_Table!$V17,Data_Long_Form!$A:$A,Data_Pivot_Table!Y$4)=0,"",SUMIFS(Data_Long_Form!$D:$D,Data_Long_Form!$C:$C,Data_Pivot_Table!$V17,Data_Long_Form!$A:$A,Data_Pivot_Table!Y$4)) -> 200.73531 | Z17: =+IF(SUMIFS(Data_Long_Form!$D:$D,Data_Long_Form!$C:$C,Data_Pivot_Table!$V17,Data_Long_Form!$A:$A,Data_Pivot_Table!Z$4)=0,"",SUMIFS(Data_Long_Form!$D:$D,Data_Long_Form!$C:$C,Data_Pivot_Table!$V17,Data_Long_Form!$A:$A,Data_Pivot_Table!Z$4)) -> 303.05223 | AA17: =+IF(SUMIFS(Data_Long_Form!$D:$D,Data_Long_Form!$C:$C,Data_Pivot_Table!$V17,Data_Long_Form!$A:$A,Data_Pivot_Table!AA$4)=0,"",SUMIFS(Data_Long_Form!$D:$D,Data_Long_Form!$C:$C,Data_Pivot_Table!$V17,Data_Long_Form!$A:$A,Data_Pivot_Table!AA$4)) -> 332.84588 | AB17: =+IF(SUMIFS(Data_Long_Form!$D:$D,Data_Long_Form!$C:$C,Data_Pivot_Table!$V17,Data_Long_Form!$A:$A,Data_Pivot_Table!AB$4)=0,"",SUMIFS(Data_Long_Form!$D:$D,Data_Long_Form!$C:$C,Data_Pivot_Table!$V17,Data_Long_Form!$A:$A,Data_Pivot_Table!AB$4)) -> 430.11621 | AC17: =+IF(SUMIFS(Data_Long_Form!$D:$D,Data_Long_Form!$C:$C,Data_Pivot_Table!$V17,Data_Long_Form!$A:$A,Data_Pivot_Table!AC$4)=0,"",SUMIFS(Data_Long_Form!$D:$D,Data_Long_Form!$C:$C,Data_Pivot_Table!$V17,Data_Long_Form!$A:$A,Data_Pivot_Table!AC$4)) -> 427.62023
A18: 0.41979167 | B18: 1 | C18: 1 | D18: 1 | E18: 1 | F18: 1 | G18: 1 | H18: 1 | I18: 7 | K18: 0.41979167 | L18: 1 | M18: 1 | N18: 1 | O18: 1 | P18: 1 | Q18: 1 | R18: 1 | S18: 7 | V18: 0.41979167 | W18: =+IF(SUMIFS(Data_Long_Form!$D:$D,Data_Long_Form!$C:$C,Data_Pivot_Table!$V18,Data_Long_Form!$A:$A,Data_Pivot_Table!W$4)=0,"",SUMIFS(Data_Long_Form!$D:$D,Data_Long_Form!$C:$C,Data_Pivot_Table!$V18,Data_Long_Form!$A:$A,Data_Pivot_Table!W$4)) -> 299.12922 | X18: =+IF(SUMIFS(Data_Long_Form!$D:$D,Data_Long_Form!$C:$C,Data_Pivot_Table!$V18,Data_Long_Form!$A:$A,Data_Pivot_Table!X$4)=0,"",SUMIFS(Data_Long_Form!$D:$D,Data_Long_Form!$C:$C,Data_Pivot_Table!$V18,Data_Long_Form!$A:$A,Data_Pivot_Table!X$4)) -> 335.9281 | Y18: =+IF(SUMIFS(Data_Long_Form!$D:$D,Data_Long_Form!$C:$C,Data_Pivot_Table!$V18,Data_Long_Form!$A:$A,Data_Pivot_Table!Y$4)=0,"",SUMIFS(Data_Long_Form!$D:$D,Data_Long_Form!$C:$C,Data_Pivot_Table!$V18,Data_Long_Form!$A:$A,Data_Pivot_Table!Y$4)) -> 198.78138 | Z18: =+IF(SUMIFS(Data_Long_Form!$D:$D,Data_Long_Form!$C:$C,Data_Pivot_Table!$V18,Data_Long_Form!$A:$A,Data_Pivot_Table!Z$4)=0,"",SUMIFS(Data_Long_Form!$D:$D,Data_Long_Form!$C:$C,Data_Pivot_Table!$V18,Data_Long_Form!$A:$A,Data_Pivot_Table!Z$4)) -> 294.75708 | AA18: =+IF(SUMIFS(Data_Long_Form!$D:$D,Data_Long_Form!$C:$C,Data_Pivot_Table!$V18,Data_Long_Form!$A:$A,Data_Pivot_Table!AA$4)=0,"",SUMIFS(Data_Long_Form!$D:$D,Data_Long_Form!$C:$C,Data_Pivot_Table!$V18,Data_Long_Form!$A:$A,Data_Pivot_Table!AA$4)) -> 348.44477 | AB18: =+IF(SUMIFS(Data_Long_Form!$D:$D,Data_Long_Form!$C:$C,Data_Pivot_Table!$V18,Data_Long_Form!$A:$A,Data_Pivot_Table!AB$4)=0,"",SUMIFS(Data_Long_Form!$D:$D,Data_Long_Form!$C:$C,Data_Pivot_Table!$V18,Data_Long_Form!$A:$A,Data_Pivot_Table!AB$4)) -> 433.50857 | AC18: =+IF(SUMIFS(Data_Long_Form!$D:$D,Data_Long_Form!$C:$C,Data_Pivot_Table!$V18,Data_Long_Form!$A:$A,Data_Pivot_Table!AC$4)=0,"",SUMIFS(Data_Long_Form!$D:$D,Data_Long_Form!$C:$C,Data_Pivot_Table!$V18,Data_Long_Form!$A:$A,Data_Pivot_Table!AC$4)) -> 422.91165
A19: 0.41980324 | E19: 1 | G19: 1 | I19: 2 | K19: 0.41980324 | M19: 1 | R19: 1 | S19: 2 | V19: 0.41980324 | W19: =+IF(SUMIFS(Data_Long_Form!$D:$D,Data_Long_Form!$C:$C,Data_Pivot_Table!$V19,Data_Long_Form!$A:$A,Data_Pivot_Table!W$4)=0,"",SUMIFS(Data_Long_Form!$D:$D,Data_Long_Form!$C:$C,Data_Pivot_Table!$V19,Data_Long_Form!$A:$A,Data_Pivot_Table!W$4)) | X19: =+IF(SUMIFS(Data_Long_Form!$D:$D,Data_Long_Form!$C:$C,Data_Pivot_Table!$V19,Data_Long_Form!$A:$A,Data_Pivot_Table!X$4)=0,"",SUMIFS(Data_Long_Form!$D:$D,Data_Long_Form!$C:$C,Data_Pivot_Table!$V19,Data_Long_Form!$A:$A,Data_Pivot_Table!X$4)) -> 340.99883 | Y19: =+IF(SUMIFS(Data_Long_Form!$D:$D,Data_Long_Form!$C:$C,Data_Pivot_Table!$V19,Data_Long_Form!$A:$A,Data_Pivot_Table!Y$4)=0,"",SUMIFS(Data_Long_Form!$D:$D,Data_Long_Form!$C:$C,Data_Pivot_Table!$V19,Data_Long_Form!$A:$A,Data_Pivot_Table!Y$4)) | Z19: =+IF(SUMIFS(Data_Long_Form!$D:$D,Data_Long_Form!$C:$C,Data_Pivot_Table!$V19,Data_Long_Form!$A:$A,Data_Pivot_Table!Z$4)=0,"",SUMIFS(Data_Long_Form!$D:$D,Data_Long_Form!$C:$C,Data_Pivot_Table!$V19,Data_Long_Form!$A:$A,Data_Pivot_Table!Z$4)) | AA19: =+IF(SUMIFS(Data_Long_Form!$D:$D,Data_Long_Form!$C:$C,Data_Pivot_Table!$V19,Data_Long_Form!$A:$A,Data_Pivot_Table!AA$4)=0,"",SUMIFS(Data_Long_Form!$D:$D,Data_Long_Form!$C:$C,Data_Pivot_Table!$V19,Data_Long_Form!$A:$A,Data_Pivot_Table!AA$4)) | AB19: =+IF(SUMIFS(Data_Long_Form!$D:$D,Data_Long_Form!$C:$C,Data_Pivot_Table!$V19,Data_Long_Form!$A:$A,Data_Pivot_Table!AB$4)=0,"",SUMIFS(Data_Long_Form!$D:$D,Data_Long_Form!$C:$C,Data_Pivot_Table!$V19,Data_Long_Form!$A:$A,Data_Pivot_Table!AB$4)) | AC19: =+IF(SUMIFS(Data_Long_Form!$D:$D,Data_Long_Form!$C:$C,Data_Pivot_Table!$V19,Data_Long_Form!$A:$A,Data_Pivot_Table!AC$4)=0,"",SUMIFS(Data_Long_Form!$D:$D,Data_Long_Form!$C:$C,Data_Pivot_Table!$V19,Data_Long_Form!$A:$A,Data_Pivot_Table!AC$4)) -> 405.15188
A20: 0.41981481 | C20: 1 | D20: 1 | E20: 1 | G20: 1 | I20: 4 | K20: 0.41981481 | M20: 1 | P20: 1 | Q20: 1 | R20: 1 | S20: 4 | V20: 0.41981481 | W20: =+IF(SUMIFS(Data_Long_Form!$D:$D,Data_Long_Form!$C:$C,Data_Pivot_Table!$V20,Data_Long_Form!$A:$A,Data_Pivot_Table!W$4)=0,"",SUMIFS(Data_Long_Form!$D:$D,Data_Long_Form!$C:$C,Data_Pivot_Table!$V20,Data_Long_Form!$A:$A,Data_Pivot_Table!W$4)) | X20: =+IF(SUMIFS(Data_Long_Form!$D:$D,Data_Long_Form!$C:$C,Data_Pivot_Table!$V20,Data_Long_Form!$A:$A,Data_Pivot_Table!X$4)=0,"",SUMIFS(Data_Long_Form!$D:$D,Data_Long_Form!$C:$C,Data_Pivot_Table!$V20,Data_Long_Form!$A:$A,Data_Pivot_Table!X$4)) -> 334.22651 | Y20: =+IF(SUMIFS(Data_Long_Form!$D:$D,Data_Long_Form!$C:$C,Data_Pivot_Table!$V20,Data_Long_Form!$A:$A,Data_Pivot_Table!Y$4)=0,"",SUMIFS(Data_Long_Form!$D:$D,Data_Long_Form!$C:$C,Data_Pivot_Table!$V20,Data_Long_Form!$A:$A,Data_Pivot_Table!Y$4)) | Z20: =+IF(SUMIFS(Data_Long_Form!$D:$D,Data_Long_Form!$C:$C,Data_Pivot_Table!$V20,Data_Long_Form!$A:$A,Data_Pivot_Table!Z$4)=0,"",SUMIFS(Data_Long_Form!$D:$D,Data_Long_Form!$C:$C,Data_Pivot_Table!$V20,Data_Long_Form!$A:$A,Data_Pivot_Table!Z$4)) | AA20: =+IF(SUMIFS(Data_Long_Form!$D:$D,Data_Long_Form!$C:$C,Data_Pivot_Table!$V20,Data_Long_Form!$A:$A,Data_Pivot_Table!AA$4)=0,"",SUMIFS(Data_Long_Form!$D:$D,Data_Long_Form!$C:$C,Data_Pivot_Table!$V20,Data_Long_Form!$A:$A,Data_Pivot_Table!AA$4)) -> 309.62907 | AB20: =+IF(SUMIFS(Data_Long_Form!$D:$D,Data_Long_Form!$C:$C,Data_Pivot_Table!$V20,Data_Long_Form!$A:$A,Data_Pivot_Table!AB$4)=0,"",SUMIFS(Data_Long_Form!$D:$D,Data_Long_Form!$C:$C,Data_Pivot_Table!$V20,Data_Long_Form!$A:$A,Data_Pivot_Table!AB$4)) -> 442.31007 | AC20: =+IF(SUMIFS(Data_Long_Form!$D:$D,Data_Long_Form!$C:$C,Data_Pivot_Table!$V20,Data_Long_Form!$A:$A,Data_Pivot_Table!AC$4)=0,"",SUMIFS(Data_Long_Form!$D:$D,Data_Long_Form!$C:$C,Data_Pivot_Table!$V20,Data_Long_Form!$A:$A,Data_Pivot_Table!AC$4)) -> 386.02452
A21: 0.41983796 | G21: 1 | I21: 1 | K21: 0.41983796 | M21: 1 | S21: 1 | V21: 0.41983796 | W21: =+IF(SUMIFS(Data_Long_Form!$D:$D,Data_Long_Form!$C:$C,Data_Pivot_Table!$V21,Data_Long_Form!$A:$A,Data_Pivot_Table!W$4)=0,"",SUMIFS(Data_Long_Form!$D:$D,Data_Long_Form!$C:$C,Data_Pivot_Table!$V21,Data_Long_Form!$A:$A,Data_Pivot_Table!W$4)) | X21: =+IF(SUMIFS(Data_Long_Form!$D:$D,Data_Long_Form!$C:$C,Data_Pivot_Table!$V21,Data_Long_Form!$A:$A,Data_Pivot_Table!X$4)=0,"",SUMIFS(Data_Long_Form!$D:$D,Data_Long_Form!$C:$C,Data_Pivot_Table!$V21,Data_Long_Form!$A:$A,Data_Pivot_Table!X$4)) -> 333.11061 | Y21: =+IF(SUMIFS(Data_Long_Form!$D:$D,Data_Long_Form!$C:$C,Data_Pivot_Table!$V21,Data_Long_Form!$A:$A,Data_Pivot_Table!Y$4)=0,"",SUMIFS(Data_Long_Form!$D:$D,Data_Long_Form!$C:$C,Data_Pivot_Table!$V21,Data_Long_Form!$A:$A,Data_Pivot_Table!Y$4)) | Z21: =+IF(SUMIFS(Data_Long_Form!$D:$D,Data_Long_Form!$C:$C,Data_Pivot_Table!$V21,Data_Long_Form!$A:$A,Data_Pivot_Table!Z$4)=0,"",SUMIFS(Data_Long_Form!$D:$D,Data_Long_Form!$C:$C,Data_Pivot_Table!$V21,Data_Long_Form!$A:$A,Data_Pivot_Table!Z$4)) | AA21: =+IF(SUMIFS(Data_Long_Form!$D:$D,Data_Long_Form!$C:$C,Data_Pivot_Table!$V21,Data_Long_Form!$A:$A,Data_Pivot_Table!AA$4)=0,"",SUMIFS(Data_Long_Form!$D:$D,Data_Long_Form!$C:$C,Data_Pivot_Table!$V21,Data_Long_Form!$A:$A,Data_Pivot_Table!AA$4)) | AB21: =+IF(SUMIFS(Data_Long_Form!$D:$D,Data_Long_Form!$C:$C,Data_Pivot_Table!$V21,Data_Long_Form!$A:$A,Data_Pivot_Table!AB$4)=0,"",SUMIFS(Data_Long_Form!$D:$D,Data_Long_Form!$C:$C,Data_Pivot_Table!$V21,Data_Long_Form!$A:$A,Data_Pivot_Table!AB$4)) | AC21: =+IF(SUMIFS(Data_Long_Form!$D:$D,Data_Long_Form!$C:$C,Data_Pivot_Table!$V21,Data_Long_Form!$A:$A,Data_Pivot_Table!AC$4)=0,"",SUMIFS(Data_Long_Form!$D:$D,Data_Long_Form!$C:$C,Data_Pivot_Table!$V21,Data_Long_Form!$A:$A,Data_Pivot_Table!AC$4))
A22: 0.41984954 | G22: 1 | I22: 1 | K22: 0.41984954 | M22: 1 | S22: 1 | V22: 0.41984954 | W22: =+IF(SUMIFS(Data_Long_Form!$D:$D,Data_Long_Form!$C:$C,Data_Pivot_Table!$V22,Data_Long_Form!$A:$A,Data_Pivot_Table!W$4)=0,"",SUMIFS(Data_Long_Form!$D:$D,Data_Long_Form!$C:$C,Data_Pivot_Table!$V22,Data_Long_Form!$A:$A,Data_Pivot_Table!W$4)) | X22: =+IF(SUMIFS(Data_Long_Form!$D:$D,Data_Long_Form!$C:$C,Data_Pivot_Table!$V22,Data_Long_Form!$A:$A,Data_Pivot_Table!X$4)=0,"",SUMIFS(Data_Long_Form!$D:$D,Data_Long_Form!$C:$C,Data_Pivot_Table!$V22,Data_Long_Form!$A:$A,Data_Pivot_Table!X$4)) -> 342.64678 | Y22: =+IF(SUMIFS(Data_Long_Form!$D:$D,Data_Long_Form!$C:$C,Data_Pivot_Table!$V22,Data_Long_Form!$A:$A,Data_Pivot_Table!Y$4)=0,"",SUMIFS(Data_Long_Form!$D:$D,Data_Long_Form!$C:$C,Data_Pivot_Table!$V22,Data_Long_Form!$A:$A,Data_Pivot_Table!Y$4)) | Z22: =+IF(SUMIFS(Data_Long_Form!$D:$D,Data_Long_Form!$C:$C,Data_Pivot_Table!$V22,Data_Long_Form!$A:$A,Data_Pivot_Table!Z$4)=0,"",SUMIFS(Data_Long_Form!$D:$D,Data_Long_Form!$C:$C,Data_Pivot_Table!$V22,Data_Long_Form!$A:$A,Data_Pivot_Table!Z$4)) | AA22: =+IF(SUMIFS(Data_Long_Form!$D:$D,Data_Long_Form!$C:$C,Data_Pivot_Table!$V22,Data_Long_Form!$A:$A,Data_Pivot_Table!AA$4)=0,"",SUMIFS(Data_Long_Form!$D:$D,Data_Long_Form!$C:$C,Data_Pivot_Table!$V22,Data_Long_Form!$A:$A,Data_Pivot_Table!AA$4)) | AB22: =+IF(SUMIFS(Data_Long_Form!$D:$D,Data_Long_Form!$C:$C,Data_Pivot_Table!$V22,Data_Long_Form!$A:$A,Data_Pivot_Table!AB$4)=0,"",SUMIFS(Data_Long_Form!$D:$D,Data_Long_Form!$C:$C,Data_Pivot_Table!$V22,Data_Long_Form!$A:$A,Data_Pivot_Table!AB$4)) | AC22: =+IF(SUMIFS(Data_Long_Form!$D:$D,Data_Long_Form!$C:$C,Data_Pivot_Table!$V22,Data_Long_Form!$A:$A,Data_Pivot_Table!AC$4)=0,"",SUMIFS(Data_Long_Form!$D:$D,Data_Long_Form!$C:$C,Data_Pivot_Table!$V22,Data_Long_Form!$A:$A,Data_Pivot_Table!AC$4))
A23: 0.41986111 | B23: 1 | F23: 1 | G23: 1 | H23: 1 | I23: 4 | K23: 0.41986111 | L23: 1 | M23: 1 | N23: 1 | O23: 1 | S23: 4 | V23: 0.41986111 | W23: =+IF(SUMIFS(Data_Long_Form!$D:$D,Data_Long_Form!$C:$C,Data_Pivot_Table!$V23,Data_Long_Form!$A:$A,Data_Pivot_Table!W$4)=0,"",SUMIFS(Data_Long_Form!$D:$D,Data_Long_Form!$C:$C,Data_Pivot_Table!$V23,Data_Long_Form!$A:$A,Data_Pivot_Table!W$4)) -> 330.76577 | X23: =+IF(SUMIFS(Data_Long_Form!$D:$D,Data_Long_Form!$C:$C,Data_Pivot_Table!$V23,Data_Long_Form!$A:$A,Data_Pivot_Table!X$4)=0,"",SUMIFS(Data_Long_Form!$D:$D,Data_Long_Form!$C:$C,Data_Pivot_Table!$V23,Data_Long_Form!$A:$A,Data_Pivot_Table!X$4)) -> 331.53421 | Y23: =+IF(SUMIFS(Data_Long_Form!$D:$D,Data_Long_Form!$C:$C,Data_Pivot_Table!$V23,Data_Long_Form!$A:$A,Data_Pivot_Table!Y$4)=0,"",SUMIFS(Data_Long_Form!$D:$D,Data_Long_Form!$C:$C,Data_Pivot_Table!$V23,Data_Long_Form!$A:$A,Data_Pivot_Table!Y$4)) -> 218.72704 | Z23: =+IF(SUMIFS(Data_Long_Form!$D:$D,Data_Long_Form!$C:$C,Data_Pivot_Table!$V23,Data_Long_Form!$A:$A,Data_Pivot_Table!Z$4)=0,"",SUMIFS(Data_Long_Form!$D:$D,Data_Long_Form!$C:$C,Data_Pivot_Table!$V23,Data_Long_Form!$A:$A,Data_Pivot_Table!Z$4)) -> 326.07129 | AA23: =+IF(SUMIFS(Data_Long_Form!$D:$D,Data_Long_Form!$C:$C,Data_Pivot_Table!$V23,Data_Long_Form!$A:$A,Data_Pivot_Table!AA$4)=0,"",SUMIFS(Data_Long_Form!$D:$D,Data_Long_Form!$C:$C,Data_Pivot_Table!$V23,Data_Long_Form!$A:$A,Data_Pivot_Table!AA$4)) | AB23: =+IF(SUMIFS(Data_Long_Form!$D:$D,Data_Long_Form!$C:$C,Data_Pivot_Table!$V23,Data_Long_Form!$A:$A,Data_Pivot_Table!AB$4)=0,"",SUMIFS(Data_Long_Form!$D:$D,Data_Long_Form!$C:$C,Data_Pivot_Table!$V23,Data_Long_Form!$A:$A,Data_Pivot_Table!AB$4)) | AC23: =+IF(SUMIFS(Data_Long_Form!$D:$D,Data_Long_Form!$C:$C,Data_Pivot_Table!$V23,Data_Long_Form!$A:$A,Data_Pivot_Table!AC$4)=0,"",SUMIFS(Data_Long_Form!$D:$D,Data_Long_Form!$C:$C,Data_Pivot_Table!$V23,Data_Long_Form!$A:$A,Data_Pivot_Table!AC$4))
A24: 0.41987269 | B24: 1 | E24: 1 | F24: 1 | G24: 1 | H24: 1 | I24: 5 | K24: 0.41987269 | L24: 1 | M24: 1 | N24: 1 | O24: 1 | R24: 1 | S24: 5 | V24: 0.41987269 | W24: =+IF(SUMIFS(Data_Long_Form!$D:$D,Data_Long_Form!$C:$C,Data_Pivot_Table!$V24,Data_Long_Form!$A:$A,Data_Pivot_Table!W$4)=0,"",SUMIFS(Data_Long_Form!$D:$D,Data_Long_Form!$C:$C,Data_Pivot_Table!$V24,Data_Long_Form!$A:$A,Data_Pivot_Table!W$4)) -> 324.15881 | X24: =+IF(SUMIFS(Data_Long_Form!$D:$D,Data_Long_Form!$C:$C,Data_Pivot_Table!$V24,Data_Long_Form!$A:$A,Data_Pivot_Table!X$4)=0,"",SUMIFS(Data_Long_Form!$D:$D,Data_Long_Form!$C:$C,Data_Pivot_Table!$V24,Data_Long_Form!$A:$A,Data_Pivot_Table!X$4)) -> 344.88562 | Y24: =+IF(SUMIFS(Data_Long_Form!$D:$D,Data_Long_Form!$C:$C,Data_Pivot_Table!$V24,Data_Long_Form!$A:$A,Data_Pivot_Table!Y$4)=0,"",SUMIFS(Data_Long_Form!$D:$D,Data_Long_Form!$C:$C,Data_Pivot_Table!$V24,Data_Long_Form!$A:$A,Data_Pivot_Table!Y$4)) -> 216.10759 | Z24: =+IF(SUMIFS(Data_Long_Form!$D:$D,Data_Long_Form!$C:$C,Data_Pivot_Table!$V24,Data_Long_Form!$A:$A,Data_Pivot_Table!Z$4)=0,"",SUMIFS(Data_Long_Form!$D:$D,Data_Long_Form!$C:$C,Data_Pivot_Table!$V24,Data_Long_Form!$A:$A,Data_Pivot_Table!Z$4)) -> 330.36944 | AA24: =+IF(SUMIFS(Data_Long_Form!$D:$D,Data_Long_Form!$C:$C,Data_Pivot_Table!$V24,Data_Long_Form!$A:$A,Data_Pivot_Table!AA$4)=0,"",SUMIFS(Data_Long_Form!$D:$D,Data_Long_Form!$C:$C,Data_Pivot_Table!$V24,Data_Long_Form!$A:$A,Data_Pivot_Table!AA$4)) | AB24: =+IF(SUMIFS(Data_Long_Form!$D:$D,Data_Long_Form!$C:$C,Data_Pivot_Table!$V24,Data_Long_Form!$A:$A,Data_Pivot_Table!AB$4)=0,"",SUMIFS(Data_Long_Form!$D:$D,Data_Long_Form!$C:$C,Data_Pivot_Table!$V24,Data_Long_Form!$A:$A,Data_Pivot_Table!AB$4)) | AC24: =+IF(SUMIFS(Data_Long_Form!$D:$D,Data_Long_Form!$C:$C,Data_Pivot_Table!$V24,Data_Long_Form!$A:$A,Data_Pivot_Table!AC$4)=0,"",SUMIFS(Data_Long_Form!$D:$D,Data_Long_Form!$C:$C,Data_Pivot_Table!$V24,Data_Long_Form!$A:$A,Data_Pivot_Table!AC$4)) -> 334.77241
A25: 0.41989583 | E25: 1 | F25: 1 | G25: 1 | I25: 3 | K25: 0.41989583 | L25: 1 | M25: 1 | R25: 1 | S25: 3 | V25: 0.41989583 | W25: =+IF(SUMIFS(Data_Long_Form!$D:$D,Data_Long_Form!$C:$C,Data_Pivot_Table!$V25,Data_Long_Form!$A:$A,Data_Pivot_Table!W$4)=0,"",SUMIFS(Data_Long_Form!$D:$D,Data_Long_Form!$C:$C,Data_Pivot_Table!$V25,Data_Long_Form!$A:$A,Data_Pivot_Table!W$4)) -> 324.43146 | X25: =+IF(SUMIFS(Data_Long_Form!$D:$D,Data_Long_Form!$C:$C,Data_Pivot_Table!$V25,Data_Long_Form!$A:$A,Data_Pivot_Table!X$4)=0,"",SUMIFS(Data_Long_Form!$D:$D,Data_Long_Form!$C:$C,Data_Pivot_Table!$V25,Data_Long_Form!$A:$A,Data_Pivot_Table!X$4)) -> 322.50881 | Y25: =+IF(SUMIFS(Data_Long_Form!$D:$D,Data_Long_Form!$C:$C,Data_Pivot_Table!$V25,Data_Long_Form!$A:$A,Data_Pivot_Table!Y$4)=0,"",SUMIFS(Data_Long_Form!$D:$D,Data_Long_Form!$C:$C,Data_Pivot_Table!$V25,Data_Long_Form!$A:$A,Data_Pivot_Table!Y$4)) | Z25: =+IF(SUMIFS(Data_Long_Form!$D:$D,Data_Long_Form!$C:$C,Data_Pivot_Table!$V25,Data_Long_Form!$A:$A,Data_Pivot_Table!Z$4)=0,"",SUMIFS(Data_Long_Form!$D:$D,Data_Long_Form!$C:$C,Data_Pivot_Table!$V25,Data_Long_Form!$A:$A,Data_Pivot_Table!Z$4)) | AA25: =+IF(SUMIFS(Data_Long_Form!$D:$D,Data_Long_Form!$C:$C,Data_Pivot_Table!$V25,Data_Long_Form!$A:$A,Data_Pivot_Table!AA$4)=0,"",SUMIFS(Data_Long_Form!$D:$D,Data_Long_Form!$C:$C,Data_Pivot_Table!$V25,Data_Long_Form!$A:$A,Data_Pivot_Table!AA$4)) | AB25: =+IF(SUMIFS(Data_Long_Form!$D:$D,Data_Long_Form!$C:$C,Data_Pivot_Table!$V25,Data_Long_Form!$A:$A,Data_Pivot_Table!AB$4)=0,"",SUMIFS(Data_Long_Form!$D:$D,Data_Long_Form!$C:$C,Data_Pivot_Table!$V25,Data_Long_Form!$A:$A,Data_Pivot_Table!AB$4)) | AC25: =+IF(SUMIFS(Data_Long_Form!$D:$D,Data_Long_Form!$C:$C,Data_Pivot_Table!$V25,Data_Long_Form!$A:$A,Data_Pivot_Table!AC$4)=0,"",SUMIFS(Data_Long_Form!$D:$D,Data_Long_Form!$C:$C,Data_Pivot_Table!$V25,Data_Long_Form!$A:$A,Data_Pivot_Table!AC$4)) -> 363.08533
A26: 0.41990741 | B26: 1 | C26: 1 | E26: 1 | F26: 1 | G26: 1 | H26: 1 | I26: 6 | K26: 0.41990741 | L26: 1 | M26: 1 | N26: 1 | O26: 1 | P26: 1 | R26: 1 | S26: 6 | V26: 0.41990741 | W26: =+IF(SUMIFS(Data_Long_Form!$D:$D,Data_Long_Form!$C:$C,Data_Pivot_Table!$V26,Data_Long_Form!$A:$A,Data_Pivot_Table!W$4)=0,"",SUMIFS(Data_Long_Form!$D:$D,Data_Long_Form!$C:$C,Data_Pivot_Table!$V26,Data_Long_Form!$A:$A,Data_Pivot_Table!W$4)) -> 325.08346 | X26: =+IF(SUMIFS(Data_Long_Form!$D:$D,Data_Long_Form!$C:$C,Data_Pivot_Table!$V26,Data_Long_Form!$A:$A,Data_Pivot_Table!X$4)=0,"",SUMIFS(Data_Long_Form!$D:$D,Data_Long_Form!$C:$C,Data_Pivot_Table!$V26,Data_Long_Form!$A:$A,Data_Pivot_Table!X$4)) -> 322.37367 | Y26: =+IF(SUMIFS(Data_Long_Form!$D:$D,Data_Long_Form!$C:$C,Data_Pivot_Table!$V26,Data_Long_Form!$A:$A,Data_Pivot_Table!Y$4)=0,"",SUMIFS(Data_Long_Form!$D:$D,Data_Long_Form!$C:$C,Data_Pivot_Table!$V26,Data_Long_Form!$A:$A,Data_Pivot_Table!Y$4)) -> 202.9186 | Z26: =+IF(SUMIFS(Data_Long_Form!$D:$D,Data_Long_Form!$C:$C,Data_Pivot_Table!$V26,Data_Long_Form!$A:$A,Data_Pivot_Table!Z$4)=0,"",SUMIFS(Data_Long_Form!$D:$D,Data_Long_Form!$C:$C,Data_Pivot_Table!$V26,Data_Long_Form!$A:$A,Data_Pivot_Table!Z$4)) -> 329.18737 | AA26: =+IF(SUMIFS(Data_Long_Form!$D:$D,Data_Long_Form!$C:$C,Data_Pivot_Table!$V26,Data_Long_Form!$A:$A,Data_Pivot_Table!AA$4)=0,"",SUMIFS(Data_Long_Form!$D:$D,Data_Long_Form!$C:$C,Data_Pivot_Table!$V26,Data_Long_Form!$A:$A,Data_Pivot_Table!AA$4)) -> 307.47509 | AB26: =+IF(SUMIFS(Data_Long_Form!$D:$D,Data_Long_Form!$C:$C,Data_Pivot_Table!$V26,Data_Long_Form!$A:$A,Data_Pivot_Table!AB$4)=0,"",SUMIFS(Data_Long_Form!$D:$D,Data_Long_Form!$C:$C,Data_Pivot_Table!$V26,Data_Long_Form!$A:$A,Data_Pivot_Table!AB$4)) | AC26: =+IF(SUMIFS(Data_Long_Form!$D:$D,Data_Long_Form!$C:$C,Data_Pivot_Table!$V26,Data_Long_Form!$A:$A,Data_Pivot_Table!AC$4)=0,"",SUMIFS(Data_Long_Form!$D:$D,Data_Long_Form!$C:$C,Data_Pivot_Table!$V26,Data_Long_Form!$A:$A,Data_Pivot_Table!AC$4)) -> 347.39086
A27: 0.41991898 | B27: 1 | C27: 1 | D27: 1 | E27: 1 | F27: 1 | G27: 1 | H27: 1 | I27: 7 | K27: 0.41991898 | L27: 1 | M27: 1 | N27: 1 | O27: 1 | P27: 1 | Q27: 1 | R27: 1 | S27: 7 | V27: 0.41991898 | W27: =+IF(SUMIFS(Data_Long_Form!$D:$D,Data_Long_Form!$C:$C,Data_Pivot_Table!$V27,Data_Long_Form!$A:$A,Data_Pivot_Table!W$4)=0,"",SUMIFS(Data_Long_Form!$D:$D,Data_Long_Form!$C:$C,Data_Pivot_Table!$V27,Data_Long_Form!$A:$A,Data_Pivot_Table!W$4)) -> 318.89795 | X27: =+IF(SUMIFS(Data_Long_Form!$D:$D,Data_Long_Form!$C:$C,Data_Pivot_Table!$V27,Data_Long_Form!$A:$A,Data_Pivot_Table!X$4)=0,"",SUMIFS(Data_Long_Form!$D:$D,Data_Long_Form!$C:$C,Data_Pivot_Table!$V27,Data_Long_Form!$A:$A,Data_Pivot_Table!X$4)) -> 322.17976 | Y27: =+IF(SUMIFS(Data_Long_Form!$D:$D,Data_Long_Form!$C:$C,Data_Pivot_Table!$V27,Data_Long_Form!$A:$A,Data_Pivot_Table!Y$4)=0,"",SUMIFS(Data_Long_Form!$D:$D,Data_Long_Form!$C:$C,Data_Pivot_Table!$V27,Data_Long_Form!$A:$A,Data_Pivot_Table!Y$4)) -> 207.89849 | Z27: =+IF(SUMIFS(Data_Long_Form!$D:$D,Data_Long_Form!$C:$C,Data_Pivot_Table!$V27,Data_Long_Form!$A:$A,Data_Pivot_Table!Z$4)=0,"",SUMIFS(Data_Long_Form!$D:$D,Data_Long_Form!$C:$C,Data_Pivot_Table!$V27,Data_Long_Form!$A:$A,Data_Pivot_Table!Z$4)) -> 330.52079 | AA27: =+IF(SUMIFS(Data_Long_Form!$D:$D,Data_Long_Form!$C:$C,Data_Pivot_Table!$V27,Data_Long_Form!$A:$A,Data_Pivot_Table!AA$4)=0,"",SUMIFS(Data_Long_Form!$D:$D,Data_Long_Form!$C:$C,Data_Pivot_Table!$V27,Data_Long_Form!$A:$A,Data_Pivot_Table!AA$4)) -> 311.57557 | AB27: =+IF(SUMIFS(Data_Long_Form!$D:$D,Data_Long_Form!$C:$C,Data_Pivot_Table!$V27,Data_Long_Form!$A:$A,Data_Pivot_Table!AB$4)=0,"",SUMIFS(Data_Long_Form!$D:$D,Data_Long_Form!$C:$C,Data_Pivot_Table!$V27,Data_Long_Form!$A:$A,Data_Pivot_Table!AB$4)) -> 452.7383 | AC27: =+IF(SUMIFS(Data_Long_Form!$D:$D,Data_Long_Form!$C:$C,Data_Pivot_Table!$V27,Data_Long_Form!$A:$A,Data_Pivot_Table!AC$4)=0,"",SUMIFS(Data_Long_Form!$D:$D,Data_Long_Form!$C:$C,Data_Pivot_Table!$V27,Data_Long_Form!$A:$A,Data_Pivot_Table!AC$4)) -> 368.17393
A28: 0.41993056 | F28: 1 | G28: 1 | I28: 2 | K28: 0.41993056 | L28: 1 | M28: 1 | S28: 2 | V28: 0.41993056 | W28: =+IF(SUMIFS(Data_Long_Form!$D:$D,Data_Long_Form!$C:$C,Data_Pivot_Table!$V28,Data_Long_Form!$A:$A,Data_Pivot_Table!W$4)=0,"",SUMIFS(Data_Long_Form!$D:$D,Data_Long_Form!$C:$C,Data_Pivot_Table!$V28,Data_Long_Form!$A:$A,Data_Pivot_Table!W$4)) -> 317.62928 | X28: =+IF(SUMIFS(Data_Long_Form!$D:$D,Data_Long_Form!$C:$C,Data_Pivot_Table!$V28,Data_Long_Form!$A:$A,Data_Pivot_Table!X$4)=0,"",SUMIFS(Data_Long_Form!$D:$D,Data_Long_Form!$C:$C,Data_Pivot_Table!$V28,Data_Long_Form!$A:$A,Data_Pivot_Table!X$4)) -> 313.89274 | Y28: =+IF(SUMIFS(Data_Long_Form!$D:$D,Data_Long_Form!$C:$C,Data_Pivot_Table!$V28,Data_Long_Form!$A:$A,Data_Pivot_Table!Y$4)=0,"",SUMIFS(Data_Long_Form!$D:$D,Data_Long_Form!$C:$C,Data_Pivot_Table!$V28,Data_Long_Form!$A:$A,Data_Pivot_Table!Y$4)) | Z28: =+IF(SUMIFS(Data_Long_Form!$D:$D,Data_Long_Form!$C:$C,Data_Pivot_Table!$V28,Data_Long_Form!$A:$A,Data_Pivot_Table!Z$4)=0,"",SUMIFS(Data_Long_Form!$D:$D,Data_Long_Form!$C:$C,Data_Pivot_Table!$V28,Data_Long_Form!$A:$A,Data_Pivot_Table!Z$4)) | AA28: =+IF(SUMIFS(Data_Long_Form!$D:$D,Data_Long_Form!$C:$C,Data_Pivot_Table!$V28,Data_Long_Form!$A:$A,Data_Pivot_Table!AA$4)=0,"",SUMIFS(Data_Long_Form!$D:$D,Data_Long_Form!$C:$C,Data_Pivot_Table!$V28,Data_Long_Form!$A:$A,Data_Pivot_Table!AA$4)) | AB28: =+IF(SUMIFS(Data_Long_Form!$D:$D,Data_Long_Form!$C:$C,Data_Pivot_Table!$V28,Data_Long_Form!$A:$A,Data_Pivot_Table!AB$4)=0,"",SUMIFS(Data_Long_Form!$D:$D,Data_Long_Form!$C:$C,Data_Pivot_Table!$V28,Data_Long_Form!$A:$A,Data_Pivot_Table!AB$4)) | AC28: =+IF(SUMIFS(Data_Long_Form!$D:$D,Data_Long_Form!$C:$C,Data_Pivot_Table!$V28,Data_Long_Form!$A:$A,Data_Pivot_Table!AC$4)=0,"",SUMIFS(Data_Long_Form!$D:$D,Data_Long_Form!$C:$C,Data_Pivot_Table!$V28,Data_Long_Form!$A:$A,Data_Pivot_Table!AC$4))
A29: 0.41994213 | B29: 1 | F29: 1 | G29: 1 | H29: 1 | I29: 4 | K29: 0.41994213 | L29: 1 | M29: 1 | N29: 1 | O29: 1 | S29: 4 | V29: 0.41994213 | W29: =+IF(SUMIFS(Data_Long_Form!$D:$D,Data_Long_Form!$C:$C,Data_Pivot_Table!$V29,Data_Long_Form!$A:$A,Data_Pivot_Table!W$4)=0,"",SUMIFS(Data_Long_Form!$D:$D,Data_Long_Form!$C:$C,Data_Pivot_Table!$V29,Data_Long_Form!$A:$A,Data_Pivot_Table!W$4)) -> 360.98468 | X29: =+IF(SUMIFS(Data_Long_Form!$D:$D,Data_Long_Form!$C:$C,Data_Pivot_Table!$V29,Data_Long_Form!$A:$A,Data_Pivot_Table!X$4)=0,"",SUMIFS(Data_Long_Form!$D:$D,Data_Long_Form!$C:$C,Data_Pivot_Table!$V29,Data_Long_Form!$A:$A,Data_Pivot_Table!X$4)) -> 348.76075 | Y29: =+IF(SUMIFS(Data_Long_Form!$D:$D,Data_Long_Form!$C:$C,Data_Pivot_Table!$V29,Data_Long_Form!$A:$A,Data_Pivot_Table!Y$4)=0,"",SUMIFS(Data_Long_Form!$D:$D,Data_Long_Form!$C:$C,Data_Pivot_Table!$V29,Data_Long_Form!$A:$A,Data_Pivot_Table!Y$4)) -> 233.85886 | Z29: =+IF(SUMIFS(Data_Long_Form!$D:$D,Data_Long_Form!$C:$C,Data_Pivot_Table!$V29,Data_Long_Form!$A:$A,Data_Pivot_Table!Z$4)=0,"",SUMIFS(Data_Long_Form!$D:$D,Data_Long_Form!$C:$C,Data_Pivot_Table!$V29,Data_Long_Form!$A:$A,Data_Pivot_Table!Z$4)) -> 363.71068 | AA29: =+IF(SUMIFS(Data_Long_Form!$D:$D,Data_Long_Form!$C:$C,Data_Pivot_Table!$V29,Data_Long_Form!$A:$A,Data_Pivot_Table!AA$4)=0,"",SUMIFS(Data_Long_Form!$D:$D,Data_Long_Form!$C:$C,Data_Pivot_Table!$V29,Data_Long_Form!$A:$A,Data_Pivot_Table!AA$4)) | AB29: =+IF(SUMIFS(Data_Long_Form!$D:$D,Data_Long_Form!$C:$C,Data_Pivot_Table!$V29,Data_Long_Form!$A:$A,Data_Pivot_Table!AB$4)=0,"",SUMIFS(Data_Long_Form!$D:$D,Data_Long_Form!$C:$C,Data_Pivot_Table!$V29,Data_Long_Form!$A:$A,Data_Pivot_Table!AB$4)) | AC29: =+IF(SUMIFS(Data_Long_Form!$D:$D,Data_Long_Form!$C:$C,Data_Pivot_Table!$V29,Data_Long_Form!$A:$A,Data_Pivot_Table!AC$4)=0,"",SUMIFS(Data_Long_Form!$D:$D,Data_Long_Form!$C:$C,Data_Pivot_Table!$V29,Data_Long_Form!$A:$A,Data_Pivot_Table!AC$4))
A30: 0.4199537 | B30: 1 | E30: 1 | F30: 1 | G30: 1 | I30: 4 | K30: 0.4199537 | L30: 1 | M30: 1 | O30: 1 | R30: 1 | S30: 4 | V30: 0.4199537 | W30: =+IF(SUMIFS(Data_Long_Form!$D:$D,Data_Long_Form!$C:$C,Data_Pivot_Table!$V30,Data_Long_Form!$A:$A,Data_Pivot_Table!W$4)=0,"",SUMIFS(Data_Long_Form!$D:$D,Data_Long_Form!$C:$C,Data_Pivot_Table!$V30,Data_Long_Form!$A:$A,Data_Pivot_Table!W$4)) -> 317.50219 | X30: =+IF(SUMIFS(Data_Long_Form!$D:$D,Data_Long_Form!$C:$C,Data_Pivot_Table!$V30,Data_Long_Form!$A:$A,Data_Pivot_Table!X$4)=0,"",SUMIFS(Data_Long_Form!$D:$D,Data_Long_Form!$C:$C,Data_Pivot_Table!$V30,Data_Long_Form!$A:$A,Data_Pivot_Table!X$4)) -> 329.40713 | Y30: =+IF(SUMIFS(Data_Long_Form!$D:$D,Data_Long_Form!$C:$C,Data_Pivot_Table!$V30,Data_Long_Form!$A:$A,Data_Pivot_Table!Y$4)=0,"",SUMIFS(Data_Long_Form!$D:$D,Data_Long_Form!$C:$C,Data_Pivot_Table!$V30,Data_Long_Form!$A:$A,Data_Pivot_Table!Y$4)) | Z30: =+IF(SUMIFS(Data_Long_Form!$D:$D,Data_Long_Form!$C:$C,Data_Pivot_Table!$V30,Data_Long_Form!$A:$A,Data_Pivot_Table!Z$4)=0,"",SUMIFS(Data_Long_Form!$D:$D,Data_Long_Form!$C:$C,Data_Pivot_Table!$V30,Data_Long_Form!$A:$A,Data_Pivot_Table!Z$4)) -> 333.73396 | AA30: =+IF(SUMIFS(Data_Long_Form!$D:$D,Data_Long_Form!$C:$C,Data_Pivot_Table!$V30,Data_Long_Form!$A:$A,Data_Pivot_Table!AA$4)=0,"",SUMIFS(Data_Long_Form!$D:$D,Data_Long_Form!$C:$C,Data_Pivot_Table!$V30,Data_Long_Form!$A:$A,Data_Pivot_Table!AA$4)) | AB30: =+IF(SUMIFS(Data_Long_Form!$D:$D,Data_Long_Form!$C:$C,Data_Pivot_Table!$V30,Data_Long_Form!$A:$A,Data_Pivot_Table!AB$4)=0,"",SUMIFS(Data_Long_Form!$D:$D,Data_Long_Form!$C:$C,Data_Pivot_Table!$V30,Data_Long_Form!$A:$A,Data_Pivot_Table!AB$4)) | AC30: =+IF(SUMIFS(Data_Long_Form!$D:$D,Data_Long_Form!$C:$C,Data_Pivot_Table!$V30,Data_Long_Form!$A:$A,Data_Pivot_Table!AC$4)=0,"",SUMIFS(Data_Long_Form!$D:$D,Data_Long_Form!$C:$C,Data_Pivot_Table!$V30,Data_Long_Form!$A:$A,Data_Pivot_Table!AC$4)) -> 347.00754
A31: 0.41996528 | B31: 1 | F31: 1 | G31: 1 | I31: 3 | K31: 0.41996528 | L31: 1 | M31: 1 | O31: 1 | S31: 3 | V31: 0.41996528 | W31: =+IF(SUMIFS(Data_Long_Form!$D:$D,Data_Long_Form!$C:$C,Data_Pivot_Table!$V31,Data_Long_Form!$A:$A,Data_Pivot_Table!W$4)=0,"",SUMIFS(Data_Long_Form!$D:$D,Data_Long_Form!$C:$C,Data_Pivot_Table!$V31,Data_Long_Form!$A:$A,Data_Pivot_Table!W$4)) -> 334.96613 | X31: =+IF(SUMIFS(Data_Long_Form!$D:$D,Data_Long_Form!$C:$C,Data_Pivot_Table!$V31,Data_Long_Form!$A:$A,Data_Pivot_Table!X$4)=0,"",SUMIFS(Data_Long_Form!$D:$D,Data_Long_Form!$C:$C,Data_Pivot_Table!$V31,Data_Long_Form!$A:$A,Data_Pivot_Table!X$4)) -> 327.2959 | Y31: =+IF(SUMIFS(Data_Long_Form!$D:$D,Data_Long_Form!$C:$C,Data_Pivot_Table!$V31,Data_Long_Form!$A:$A,Data_Pivot_Table!Y$4)=0,"",SUMIFS(Data_Long_Form!$D:$D,Data_Long_Form!$C:$C,Data_Pivot_Table!$V31,Data_Long_Form!$A:$A,Data_Pivot_Table!Y$4)) | Z31: =+IF(SUMIFS(Data_Long_Form!$D:$D,Data_Long_Form!$C:$C,Data_Pivot_Table!$V31,Data_Long_Form!$A:$A,Data_Pivot_Table!Z$4)=0,"",SUMIFS(Data_Long_Form!$D:$D,Data_Long_Form!$C:$C,Data_Pivot_Table!$V31,Data_Long_Form!$A:$A,Data_Pivot_Table!Z$4)) -> 334.74395 | AA31: =+IF(SUMIFS(Data_Long_Form!$D:$D,Data_Long_Form!$C:$C,Data_Pivot_Table!$V31,Data_Long_Form!$A:$A,Data_Pivot_Table!AA$4)=0,"",SUMIFS(Data_Long_Form!$D:$D,Data_Long_Form!$C:$C,Data_Pivot_Table!$V31,Data_Long_Form!$A:$A,Data_Pivot_Table!AA$4)) | AB31: =+IF(SUMIFS(Data_Long_Form!$D:$D,Data_Long_Form!$C:$C,Data_Pivot_Table!$V31,Data_Long_Form!$A:$A,Data_Pivot_Table!AB$4)=0,"",SUMIFS(Data_Long_Form!$D:$D,Data_Long_Form!$C:$C,Data_Pivot_Table!$V31,Data_Long_Form!$A:$A,Data_Pivot_Table!AB$4)) | AC31: =+IF(SUMIFS(Data_Long_Form!$D:$D,Data_Long_Form!$C:$C,Data_Pivot_Table!$V31,Data_Long_Form!$A:$A,Data_Pivot_Table!AC$4)=0,"",SUMIFS(Data_Long_Form!$D:$D,Data_Long_Form!$C:$C,Data_Pivot_Table!$V31,Data_Long_Form!$A:$A,Data_Pivot_Table!AC$4))
A32: 0.41997685 | B32: 1 | C32: 1 | D32: 1 | E32: 1 | F32: 1 | G32: 1 | H32: 1 | I32: 7 | K32: 0.41997685 | L32: 1 | M32: 1 | N32: 1 | O32: 1 | P32: 1 | Q32: 1 | R32: 1 | S32: 7 | V32: 0.41997685 | W32: =+IF(SUMIFS(Data_Long_Form!$D:$D,Data_Long_Form!$C:$C,Data_Pivot_Table!$V32,Data_Long_Form!$A:$A,Data_Pivot_Table!W$4)=0,"",SUMIFS(Data_Long_Form!$D:$D,Data_Long_Form!$C:$C,Data_Pivot_Table!$V32,Data_Long_Form!$A:$A,Data_Pivot_Table!W$4)) -> 342.43745 | X32: =+IF(SUMIFS(Data_Long_Form!$D:$D,Data_Long_Form!$C:$C,Data_Pivot_Table!$V32,Data_Long_Form!$A:$A,Data_Pivot_Table!X$4)=0,"",SUMIFS(Data_Long_Form!$D:$D,Data_Long_Form!$C:$C,Data_Pivot_Table!$V32,Data_Long_Form!$A:$A,Data_Pivot_Table!X$4)) -> 330.12176 | Y32: =+IF(SUMIFS(Data_Long_Form!$D:$D,Data_Long_Form!$C:$C,Data_Pivot_Table!$V32,Data_Long_Form!$A:$A,Data_Pivot_Table!Y$4)=0,"",SUMIFS(Data_Long_Form!$D:$D,Data_Long_Form!$C:$C,Data_Pivot_Table!$V32,Data_Long_Form!$A:$A,Data_Pivot_Table!Y$4)) -> 191.05478 | Z32: =+IF(SUMIFS(Data_Long_Form!$D:$D,Data_Long_Form!$C:$C,Data_Pivot_Table!$V32,Data_Long_Form!$A:$A,Data_Pivot_Table!Z$4)=0,"",SUMIFS(Data_Long_Form!$D:$D,Data_Long_Form!$C:$C,Data_Pivot_Table!$V32,Data_Long_Form!$A:$A,Data_Pivot_Table!Z$4)) -> 339.43942 | AA32: =+IF(SUMIFS(Data_Long_Form!$D:$D,Data_Long_Form!$C:$C,Data_Pivot_Table!$V32,Data_Long_Form!$A:$A,Data_Pivot_Table!AA$4)=0,"",SUMIFS(Data_Long_Form!$D:$D,Data_Long_Form!$C:$C,Data_Pivot_Table!$V32,Data_Long_Form!$A:$A,Data_Pivot_Table!AA$4)) -> 351.76129 | AB32: =+IF(SUMIFS(Data_Long_Form!$D:$D,Data_Long_Form!$C:$C,Data_Pivot_Table!$V32,Data_Long_Form!$A:$A,Data_Pivot_Table!AB$4)=0,"",SUMIFS(Data_Long_Form!$D:$D,Data_Long_Form!$C:$C,Data_Pivot_Table!$V32,Data_Long_Form!$A:$A,Data_Pivot_Table!AB$4)) -> 430.56261 | AC32: =+IF(SUMIFS(Data_Long_Form!$D:$D,Data_Long_Form!$C:$C,Data_Pivot_Table!$V32,Data_Long_Form!$A:$A,Data_Pivot_Table!AC$4)=0,"",SUMIFS(Data_Long_Form!$D:$D,Data_Long_Form!$C:$C,Data_Pivot_Table!$V32,Data_Long_Form!$A:$A,Data_Pivot_Table!AC$4)) -> 354.45719
